ERROR 2025-09-22 05:33:39,586 views 1556874 140388715673408 Error logging registration activity: 'Event' object has no attribute 'name'
ERROR 2025-09-22 05:33:45,121 views 1556874 140388715673408 Error logging cancellation activity: 'Event' object has no attribute 'name'
Internal Server Error: /api/v1/events/803cc868-db82-4e9e-bba4-4e789b1e6b80/cancel/
Traceback (most recent call last):
  File "/home/almalinux/.local/lib/python3.9/site-packages/django/core/handlers/exception.py", line 55, in inner
    response = get_response(request)
  File "/home/almalinux/.local/lib/python3.9/site-packages/django/core/handlers/base.py", line 197, in _get_response
    response = wrapped_callback(request, *callback_args, **callback_kwargs)
  File "/home/almalinux/.local/lib/python3.9/site-packages/django/views/decorators/csrf.py", line 56, in wrapper_view
    return view_func(*args, **kwargs)
  File "/home/almalinux/.local/lib/python3.9/site-packages/django/views/generic/base.py", line 104, in view
    return self.dispatch(request, *args, **kwargs)
  File "/home/almalinux/.local/lib/python3.9/site-packages/rest_framework/views.py", line 509, in dispatch
    response = self.handle_exception(exc)
  File "/home/almalinux/.local/lib/python3.9/site-packages/rest_framework/views.py", line 469, in handle_exception
    self.raise_uncaught_exception(exc)
  File "/home/almalinux/.local/lib/python3.9/site-packages/rest_framework/views.py", line 480, in raise_uncaught_exception
    raise exc
  File "/home/almalinux/.local/lib/python3.9/site-packages/rest_framework/views.py", line 506, in dispatch
    response = handler(request, *args, **kwargs)
  File "/srv/casaaustin/api-casa-austin/src/apps/events/views.py", line 297, in delete
    'event_name': event.name,
AttributeError: 'Event' object has no attribute 'name'
ERROR 2025-09-22 05:33:45,132 log 1556874 140388715673408 Internal Server Error: /api/v1/events/803cc868-db82-4e9e-bba4-4e789b1e6b80/cancel/
Traceback (most recent call last):
  File "/home/almalinux/.local/lib/python3.9/site-packages/django/core/handlers/exception.py", line 55, in inner
    response = get_response(request)
  File "/home/almalinux/.local/lib/python3.9/site-packages/django/core/handlers/base.py", line 197, in _get_response
    response = wrapped_callback(request, *callback_args, **callback_kwargs)
  File "/home/almalinux/.local/lib/python3.9/site-packages/django/views/decorators/csrf.py", line 56, in wrapper_view
    return view_func(*args, **kwargs)
  File "/home/almalinux/.local/lib/python3.9/site-packages/django/views/generic/base.py", line 104, in view
    return self.dispatch(request, *args, **kwargs)
  File "/home/almalinux/.local/lib/python3.9/site-packages/rest_framework/views.py", line 509, in dispatch
    response = self.handle_exception(exc)
  File "/home/almalinux/.local/lib/python3.9/site-packages/rest_framework/views.py", line 469, in handle_exception
    self.raise_uncaught_exception(exc)
  File "/home/almalinux/.local/lib/python3.9/site-packages/rest_framework/views.py", line 480, in raise_uncaught_exception
    raise exc
  File "/home/almalinux/.local/lib/python3.9/site-packages/rest_framework/views.py", line 506, in dispatch
    response = handler(request, *args, **kwargs)
  File "/srv/casaaustin/api-casa-austin/src/apps/events/views.py", line 297, in delete
    'event_name': event.name,
AttributeError: 'Event' object has no attribute 'name'