➜  src git:(main) ✗ gunicorn --bind 0.0.0.0:8000 config.wsgi:application
[2025-08-20 08:38:25 -0500] [937189] [INFO] Starting gunicorn 21.2.0
[2025-08-20 08:38:25 -0500] [937189] [INFO] Listening at: http://0.0.0.0:8000 (937189)
[2025-08-20 08:38:25 -0500] [937189] [INFO] Using worker: sync
[2025-08-20 08:38:25 -0500] [937190] [INFO] Booting worker with pid: 937190
Internal Server Error: /django-admin/property/automaticdiscount/add/
Traceback (most recent call last):
  File "/home/almalinux/.local/lib/python3.9/site-packages/django/db/backends/utils.py", line 89, in _execute
    return self.cursor.execute(sql, params)
  File "/home/almalinux/.local/lib/python3.9/site-packages/django/db/backends/mysql/base.py", line 75, in execute
    return self.cursor.execute(query, args)
  File "/home/almalinux/.local/lib/python3.9/site-packages/MySQLdb/cursors.py", line 179, in execute
    res = self._query(mogrified_query)
  File "/home/almalinux/.local/lib/python3.9/site-packages/MySQLdb/cursors.py", line 330, in _query
    db.query(q)
  File "/home/almalinux/.local/lib/python3.9/site-packages/MySQLdb/connections.py", line 261, in query
    _mysql.connection.query(self, query)
MySQLdb.DataError: (1406, "Data too long for column 'trigger' at row 1")

The above exception was the direct cause of the following exception:

Traceback (most recent call last):
  File "/home/almalinux/.local/lib/python3.9/site-packages/django/core/handlers/exception.py", line 55, in inner
    response = get_response(request)
  File "/home/almalinux/.local/lib/python3.9/site-packages/django/core/handlers/base.py", line 197, in _get_response
    response = wrapped_callback(request, *callback_args, **callback_kwargs)
  File "/home/almalinux/.local/lib/python3.9/site-packages/django/contrib/admin/options.py", line 688, in wrapper
    return self.admin_site.admin_view(view)(*args, **kwargs)
  File "/home/almalinux/.local/lib/python3.9/site-packages/django/utils/decorators.py", line 134, in _wrapper_view
    response = view_func(request, *args, **kwargs)
  File "/home/almalinux/.local/lib/python3.9/site-packages/django/views/decorators/cache.py", line 62, in _wrapper_view_func
    response = view_func(request, *args, **kwargs)
  File "/home/almalinux/.local/lib/python3.9/site-packages/django/contrib/admin/sites.py", line 242, in inner
    return view(request, *args, **kwargs)
  File "/home/almalinux/.local/lib/python3.9/site-packages/django/contrib/admin/options.py", line 1886, in add_view
    return self.changeform_view(request, None, form_url, extra_context)
  File "/home/almalinux/.local/lib/python3.9/site-packages/django/utils/decorators.py", line 46, in _wrapper
    return bound_method(*args, **kwargs)
  File "/home/almalinux/.local/lib/python3.9/site-packages/django/utils/decorators.py", line 134, in _wrapper_view
    response = view_func(request, *args, **kwargs)
  File "/home/almalinux/.local/lib/python3.9/site-packages/django/contrib/admin/options.py", line 1747, in changeform_view
    return self._changeform_view(request, object_id, form_url, extra_context)
  File "/home/almalinux/.local/lib/python3.9/site-packages/django/contrib/admin/options.py", line 1798, in _changeform_view
    self.save_model(request, new_object, form, not add)
  File "/home/almalinux/.local/lib/python3.9/site-packages/django/contrib/admin/options.py", line 1227, in save_model
    obj.save()
  File "/home/almalinux/.local/lib/python3.9/site-packages/django/db/models/base.py", line 814, in save
    self.save_base(
  File "/home/almalinux/.local/lib/python3.9/site-packages/django/db/models/base.py", line 877, in save_base
    updated = self._save_table(
  File "/home/almalinux/.local/lib/python3.9/site-packages/django/db/models/base.py", line 1020, in _save_table
    results = self._do_insert(
  File "/home/almalinux/.local/lib/python3.9/site-packages/django/db/models/base.py", line 1061, in _do_insert
    return manager._insert(
  File "/home/almalinux/.local/lib/python3.9/site-packages/django/db/models/manager.py", line 87, in manager_method
    return getattr(self.get_queryset(), name)(*args, **kwargs)
  File "/home/almalinux/.local/lib/python3.9/site-packages/django/db/models/query.py", line 1805, in _insert
    return query.get_compiler(using=using).execute_sql(returning_fields)
  File "/home/almalinux/.local/lib/python3.9/site-packages/django/db/models/sql/compiler.py", line 1822, in execute_sql
    cursor.execute(sql, params)
  File "/home/almalinux/.local/lib/python3.9/site-packages/django/db/backends/utils.py", line 102, in execute
    return super().execute(sql, params)
  File "/home/almalinux/.local/lib/python3.9/site-packages/django/db/backends/utils.py", line 67, in execute
    return self._execute_with_wrappers(
  File "/home/almalinux/.local/lib/python3.9/site-packages/django/db/backends/utils.py", line 80, in _execute_with_wrappers
    return executor(sql, params, many, context)
  File "/home/almalinux/.local/lib/python3.9/site-packages/django/db/backends/utils.py", line 89, in _execute
    return self.cursor.execute(sql, params)
  File "/home/almalinux/.local/lib/python3.9/site-packages/django/db/utils.py", line 91, in __exit__
    raise dj_exc_value.with_traceback(traceback) from exc_value
  File "/home/almalinux/.local/lib/python3.9/site-packages/django/db/backends/utils.py", line 89, in _execute
    return self.cursor.execute(sql, params)
  File "/home/almalinux/.local/lib/python3.9/site-packages/django/db/backends/mysql/base.py", line 75, in execute
    return self.cursor.execute(query, args)
  File "/home/almalinux/.local/lib/python3.9/site-packages/MySQLdb/cursors.py", line 179, in execute
    res = self._query(mogrified_query)
  File "/home/almalinux/.local/lib/python3.9/site-packages/MySQLdb/cursors.py", line 330, in _query
    db.query(q)
  File "/home/almalinux/.local/lib/python3.9/site-packages/MySQLdb/connections.py", line 261, in query
    _mysql.connection.query(self, query)
django.db.utils.DataError: (1406, "Data too long for column 'trigger' at row 1")
ERROR 2025-08-20 08:38:31,821 log 937190 140352632104768 Internal Server Error: /django-admin/property/automaticdiscount/add/
Traceback (most recent call last):
  File "/home/almalinux/.local/lib/python3.9/site-packages/django/db/backends/utils.py", line 89, in _execute
    return self.cursor.execute(sql, params)
  File "/home/almalinux/.local/lib/python3.9/site-packages/django/db/backends/mysql/base.py", line 75, in execute
    return self.cursor.execute(query, args)
  File "/home/almalinux/.local/lib/python3.9/site-packages/MySQLdb/cursors.py", line 179, in execute
    res = self._query(mogrified_query)
  File "/home/almalinux/.local/lib/python3.9/site-packages/MySQLdb/cursors.py", line 330, in _query
    db.query(q)
  File "/home/almalinux/.local/lib/python3.9/site-packages/MySQLdb/connections.py", line 261, in query
    _mysql.connection.query(self, query)
MySQLdb.DataError: (1406, "Data too long for column 'trigger' at row 1")

The above exception was the direct cause of the following exception:

Traceback (most recent call last):
  File "/home/almalinux/.local/lib/python3.9/site-packages/django/core/handlers/exception.py", line 55, in inner
    response = get_response(request)
  File "/home/almalinux/.local/lib/python3.9/site-packages/django/core/handlers/base.py", line 197, in _get_response
    response = wrapped_callback(request, *callback_args, **callback_kwargs)
  File "/home/almalinux/.local/lib/python3.9/site-packages/django/contrib/admin/options.py", line 688, in wrapper
    return self.admin_site.admin_view(view)(*args, **kwargs)
  File "/home/almalinux/.local/lib/python3.9/site-packages/django/utils/decorators.py", line 134, in _wrapper_view
    response = view_func(request, *args, **kwargs)
  File "/home/almalinux/.local/lib/python3.9/site-packages/django/views/decorators/cache.py", line 62, in _wrapper_view_func
    response = view_func(request, *args, **kwargs)
  File "/home/almalinux/.local/lib/python3.9/site-packages/django/contrib/admin/sites.py", line 242, in inner
    return view(request, *args, **kwargs)
  File "/home/almalinux/.local/lib/python3.9/site-packages/django/contrib/admin/options.py", line 1886, in add_view
    return self.changeform_view(request, None, form_url, extra_context)
  File "/home/almalinux/.local/lib/python3.9/site-packages/django/utils/decorators.py", line 46, in _wrapper
    return bound_method(*args, **kwargs)
  File "/home/almalinux/.local/lib/python3.9/site-packages/django/utils/decorators.py", line 134, in _wrapper_view
    response = view_func(request, *args, **kwargs)
  File "/home/almalinux/.local/lib/python3.9/site-packages/django/contrib/admin/options.py", line 1747, in changeform_view
    return self._changeform_view(request, object_id, form_url, extra_context)
  File "/home/almalinux/.local/lib/python3.9/site-packages/django/contrib/admin/options.py", line 1798, in _changeform_view
    self.save_model(request, new_object, form, not add)
  File "/home/almalinux/.local/lib/python3.9/site-packages/django/contrib/admin/options.py", line 1227, in save_model
    obj.save()
  File "/home/almalinux/.local/lib/python3.9/site-packages/django/db/models/base.py", line 814, in save
    self.save_base(
  File "/home/almalinux/.local/lib/python3.9/site-packages/django/db/models/base.py", line 877, in save_base
    updated = self._save_table(
  File "/home/almalinux/.local/lib/python3.9/site-packages/django/db/models/base.py", line 1020, in _save_table
    results = self._do_insert(
  File "/home/almalinux/.local/lib/python3.9/site-packages/django/db/models/base.py", line 1061, in _do_insert
    return manager._insert(
  File "/home/almalinux/.local/lib/python3.9/site-packages/django/db/models/manager.py", line 87, in manager_method
    return getattr(self.get_queryset(), name)(*args, **kwargs)
  File "/home/almalinux/.local/lib/python3.9/site-packages/django/db/models/query.py", line 1805, in _insert
    return query.get_compiler(using=using).execute_sql(returning_fields)
  File "/home/almalinux/.local/lib/python3.9/site-packages/django/db/models/sql/compiler.py", line 1822, in execute_sql
    cursor.execute(sql, params)
  File "/home/almalinux/.local/lib/python3.9/site-packages/django/db/backends/utils.py", line 102, in execute
    return super().execute(sql, params)
  File "/home/almalinux/.local/lib/python3.9/site-packages/django/db/backends/utils.py", line 67, in execute
    return self._execute_with_wrappers(
  File "/home/almalinux/.local/lib/python3.9/site-packages/django/db/backends/utils.py", line 80, in _execute_with_wrappers
    return executor(sql, params, many, context)
  File "/home/almalinux/.local/lib/python3.9/site-packages/django/db/backends/utils.py", line 89, in _execute
    return self.cursor.execute(sql, params)
  File "/home/almalinux/.local/lib/python3.9/site-packages/django/db/utils.py", line 91, in __exit__
    raise dj_exc_value.with_traceback(traceback) from exc_value
  File "/home/almalinux/.local/lib/python3.9/site-packages/django/db/backends/utils.py", line 89, in _execute
    return self.cursor.execute(sql, params)
  File "/home/almalinux/.local/lib/python3.9/site-packages/django/db/backends/mysql/base.py", line 75, in execute
    return self.cursor.execute(query, args)
  File "/home/almalinux/.local/lib/python3.9/site-packages/MySQLdb/cursors.py", line 179, in execute
    res = self._query(mogrified_query)
  File "/home/almalinux/.local/lib/python3.9/site-packages/MySQLdb/cursors.py", line 330, in _query
    db.query(q)
  File "/home/almalinux/.local/lib/python3.9/site-packages/MySQLdb/connections.py", line 261, in query
    _mysql.connection.query(self, query)
django.db.utils.DataError: (1406, "Data too long for column 'trigger' at row 1")