‚ûú  src git:(main) ‚úó gunicorn --bind 0.0.0.0:8000 config.wsgi:application
[2025-09-21 09:06:08 -0500] [1254914] [INFO] Starting gunicorn 21.2.0
[2025-09-21 09:06:08 -0500] [1254914] [INFO] Listening at: http://0.0.0.0:8000 (1254914)
[2025-09-21 09:06:08 -0500] [1254914] [INFO] Using worker: sync
[2025-09-21 09:06:08 -0500] [1254915] [INFO] Booting worker with pid: 1254915
INFO 2025-09-21 09:06:12,129 signals 1254915 140585264379712 üî• SIGNAL EJECUTADO: Nueva reserva creada ID f4d3372c-49c0-4a32-8578-0f38daab9307 - Origen: aus - Cliente: Clients object (56da635c-9133-4269-bcaa-44423d610755)
DEBUG 2025-09-21 09:06:12,130 signals 1254915 140585264379712 Enviando mensaje de Telegram: üìû **AUSTIN** - Reserva en Casa Austin 1
Cliente: Catherine Silvanna Arenas Chacon
Check-in : Domingo 21 de septiembre
Check-out : Lunes 22 de septiembre
Invitados : 4
Temperado : No
Precio (USD) : 85.00 d√≥lares
Precio (Soles) : 314.50 soles
Adelanto : 42.50 USD
Tel√©fono : +51986778584 con imagen: None
DEBUG 2025-09-21 09:06:12,130 telegram_notifier 1254915 140585264379712 Preparando para enviar mensaje: üìû **AUSTIN** - Reserva en Casa Austin 1
Cliente: Catherine Silvanna Arenas Chacon
Check-in : Domingo 21 de septiembre
Check-out : Lunes 22 de septiembre
Invitados : 4
Temperado : No
Precio (USD) : 85.00 d√≥lares
Precio (Soles) : 314.50 soles
Adelanto : 42.50 USD
Tel√©fono : +51986778584
DEBUG 2025-09-21 09:06:12,130 telegram_notifier 1254915 140585264379712 Enviando mensaje asincr√≥nicamente a Telegram.
INFO 2025-09-21 09:06:12,566 _client 1254915 140585264379712 HTTP Request: POST https://api.telegram.org/bot7321656705:AAEXB3h3x0Le4h9csLF8l0MP9HMbEytPfX0/sendMessage "HTTP/1.1 200 OK"
DEBUG 2025-09-21 09:06:12,566 telegram_notifier 1254915 140585264379712 Mensaje enviado.
DEBUG 2025-09-21 09:06:12,566 telegram_notifier 1254915 140585264379712 Mensaje enviado a trav√©s del executor.
DEBUG 2025-09-21 09:06:12,566 signals 1254915 140585264379712 Reserva para el mismo d√≠a detectada, enviando al segundo canal.
DEBUG 2025-09-21 09:06:12,567 telegram_notifier 1254915 140585264379712 Preparando para enviar mensaje: ******PARA HOYYYY******
Cliente: Catherine Silvanna Arenas Chacon
Check-in : Domingo 21 de septiembre
Check-out : Lunes 22 de septiembre
Invitados : 4
Temperado : No

DEBUG 2025-09-21 09:06:12,567 telegram_notifier 1254915 140585264379712 Enviando mensaje asincr√≥nicamente a Telegram.
INFO 2025-09-21 09:06:12,835 _client 1254915 140585264379712 HTTP Request: POST https://api.telegram.org/bot7321656705:AAEXB3h3x0Le4h9csLF8l0MP9HMbEytPfX0/sendMessage "HTTP/1.1 200 OK"
DEBUG 2025-09-21 09:06:12,836 telegram_notifier 1254915 140585264379712 Mensaje enviado.
DEBUG 2025-09-21 09:06:12,836 telegram_notifier 1254915 140585264379712 Mensaje enviado a trav√©s del executor.
DEBUG 2025-09-21 09:06:12,836 telegram_notifier 1254915 140585264379712 Preparando para enviar mensaje: ******Reserva en Casa Austin 1******
Cliente: Catherine Silvanna Arenas Chacon
Cumplea√±os: S√°bado 15 de febrero (Cumple 29 a√±os)
Check-in : Domingo 21 de septiembre
Check-out : Lunes 22 de septiembre
Invitados : 4
Temperado : No
Tel√©fono : https://wa.me/51986778584
DEBUG 2025-09-21 09:06:12,836 telegram_notifier 1254915 140585264379712 Enviando mensaje asincr√≥nicamente a Telegram.
INFO 2025-09-21 09:06:13,144 _client 1254915 140585264379712 HTTP Request: POST https://api.telegram.org/bot7321656705:AAEXB3h3x0Le4h9csLF8l0MP9HMbEytPfX0/sendMessage "HTTP/1.1 200 OK"
DEBUG 2025-09-21 09:06:13,146 telegram_notifier 1254915 140585264379712 Mensaje enviado.
DEBUG 2025-09-21 09:06:13,146 telegram_notifier 1254915 140585264379712 Mensaje enviado a trav√©s del executor.
INFO 2025-09-21 09:06:13,146 signals 1254915 140585264379712 üéØ Intentando crear actividad de feed para reserva f4d3372c-49c0-4a32-8578-0f38daab9307
ERROR 2025-09-21 09:06:13,149 signals 1254915 140585264379712 ‚ùå Error creando actividad de nueva reserva para reserva f4d3372c-49c0-4a32-8578-0f38daab9307: (1364, "Field 'reason' doesn't have a default value")
ERROR 2025-09-21 09:06:13,151 signals 1254915 140585264379712 üìä Traceback completo: Traceback (most recent call last):
  File "/home/almalinux/.local/lib/python3.9/site-packages/django/db/backends/utils.py", line 89, in _execute
    return self.cursor.execute(sql, params)
  File "/home/almalinux/.local/lib/python3.9/site-packages/django/db/backends/mysql/base.py", line 75, in execute
    return self.cursor.execute(query, args)
  File "/home/almalinux/.local/lib/python3.9/site-packages/MySQLdb/cursors.py", line 179, in execute
    res = self._query(mogrified_query)
  File "/home/almalinux/.local/lib/python3.9/site-packages/MySQLdb/cursors.py", line 330, in _query
    db.query(q)
  File "/home/almalinux/.local/lib/python3.9/site-packages/MySQLdb/connections.py", line 255, in query
    _mysql.connection.query(self, query)
MySQLdb.IntegrityError: (1364, "Field 'reason' doesn't have a default value")

The above exception was the direct cause of the following exception:

Traceback (most recent call last):
  File "/srv/casaaustin/api-casa-austin/src/apps/reservation/signals.py", line 829, in reservation_post_save_handler
    activity = ActivityFeed.create_activity(
  File "/srv/casaaustin/api-casa-austin/src/apps/events/models.py", line 645, in create_activity
    return cls.objects.create(
  File "/home/almalinux/.local/lib/python3.9/site-packages/django/db/models/manager.py", line 87, in manager_method
    return getattr(self.get_queryset(), name)(*args, **kwargs)
  File "/home/almalinux/.local/lib/python3.9/site-packages/django/db/models/query.py", line 658, in create
    obj.save(force_insert=True, using=self.db)
  File "/home/almalinux/.local/lib/python3.9/site-packages/django/db/models/base.py", line 814, in save
    self.save_base(
  File "/home/almalinux/.local/lib/python3.9/site-packages/django/db/models/base.py", line 877, in save_base
    updated = self._save_table(
  File "/home/almalinux/.local/lib/python3.9/site-packages/django/db/models/base.py", line 1020, in _save_table
    results = self._do_insert(
  File "/home/almalinux/.local/lib/python3.9/site-packages/django/db/models/base.py", line 1061, in _do_insert
    return manager._insert(
  File "/home/almalinux/.local/lib/python3.9/site-packages/django/db/models/manager.py", line 87, in manager_method
    return getattr(self.get_queryset(), name)(*args, **kwargs)
  File "/home/almalinux/.local/lib/python3.9/site-packages/django/db/models/query.py", line 1805, in _insert
    return query.get_compiler(using=using).execute_sql(returning_fields)
  File "/home/almalinux/.local/lib/python3.9/site-packages/django/db/models/sql/compiler.py", line 1820, in execute_sql
    cursor.execute(sql, params)
  File "/home/almalinux/.local/lib/python3.9/site-packages/django/db/backends/utils.py", line 102, in execute
    return super().execute(sql, params)
  File "/home/almalinux/.local/lib/python3.9/site-packages/django/db/backends/utils.py", line 67, in execute
    return self._execute_with_wrappers(
  File "/home/almalinux/.local/lib/python3.9/site-packages/django/db/backends/utils.py", line 80, in _execute_with_wrappers
    return executor(sql, params, many, context)
  File "/home/almalinux/.local/lib/python3.9/site-packages/django/db/backends/utils.py", line 89, in _execute
    return self.cursor.execute(sql, params)
  File "/home/almalinux/.local/lib/python3.9/site-packages/django/db/utils.py", line 91, in __exit__
    raise dj_exc_value.with_traceback(traceback) from exc_value
  File "/home/almalinux/.local/lib/python3.9/site-packages/django/db/backends/utils.py", line 89, in _execute
    return self.cursor.execute(sql, params)
  File "/home/almalinux/.local/lib/python3.9/site-packages/django/db/backends/mysql/base.py", line 75, in execute
    return self.cursor.execute(query, args)
  File "/home/almalinux/.local/lib/python3.9/site-packages/MySQLdb/cursors.py", line 179, in execute
    res = self._query(mogrified_query)
  File "/home/almalinux/.local/lib/python3.9/site-packages/MySQLdb/cursors.py", line 330, in _query
    db.query(q)
  File "/home/almalinux/.local/lib/python3.9/site-packages/MySQLdb/connections.py", line 255, in query
    _mysql.connection.query(self, query)
django.db.utils.IntegrityError: (1364, "Field 'reason' doesn't have a default value")

INFO 2025-09-21 09:06:13,151 signals 1254915 140585264379712 New reservation created with approved status f4d3372c-49c0-4a32-8578-0f38daab9307 - Creating automatic cleaning task
ERROR 2025-09-21 09:06:13,152 signals 1254915 140585264379712 ‚ùå Error creating automatic cleaning task for reservation f4d3372c-49c0-4a32-8578-0f38daab9307: An error occurred in the current transaction. You can't execute queries until the end of the 'atomic' block.
INFO 2025-09-21 09:06:13,152 signals 1254915 140585264379712 üß† EVALUANDO reorganizaci√≥n por nueva reserva f4d3372c-49c0-4a32-8578-0f38daab9307
INFO 2025-09-21 09:06:13,153 signals 1254915 140585264379712 üîç Nueva reserva f4d3372c-49c0-4a32-8578-0f38daab9307 (check-in 2025-09-21)
ERROR 2025-09-21 09:06:13,153 signals 1254915 140585264379712 Error buscando tareas afectadas por reserva f4d3372c-49c0-4a32-8578-0f38daab9307: An error occurred in the current transaction. You can't execute queries until the end of the 'atomic' block.
INFO 2025-09-21 09:06:13,153 signals 1254915 140585264379712 ‚úÖ No hay tareas que requieran reorganizaci√≥n
Error creando actividad de reserva: An error occurred in the current transaction. You can't execute queries until the end of the 'atomic' block.
Internal Server Error: /api/v1/reservations/
Traceback (most recent call last):
  File "/home/almalinux/.local/lib/python3.9/site-packages/django/db/backends/utils.py", line 89, in _execute
    return self.cursor.execute(sql, params)
  File "/home/almalinux/.local/lib/python3.9/site-packages/django/db/backends/mysql/base.py", line 75, in execute
    return self.cursor.execute(query, args)
  File "/home/almalinux/.local/lib/python3.9/site-packages/MySQLdb/cursors.py", line 179, in execute
    res = self._query(mogrified_query)
  File "/home/almalinux/.local/lib/python3.9/site-packages/MySQLdb/cursors.py", line 330, in _query
    db.query(q)
  File "/home/almalinux/.local/lib/python3.9/site-packages/MySQLdb/connections.py", line 255, in query
    _mysql.connection.query(self, query)
MySQLdb.IntegrityError: (1364, "Field 'reason' doesn't have a default value")

The above exception was the direct cause of the following exception:

Traceback (most recent call last):
  File "/srv/casaaustin/api-casa-austin/src/apps/reservation/signals.py", line 829, in reservation_post_save_handler
    activity = ActivityFeed.create_activity(
  File "/srv/casaaustin/api-casa-austin/src/apps/events/models.py", line 645, in create_activity
    return cls.objects.create(
  File "/home/almalinux/.local/lib/python3.9/site-packages/django/db/models/manager.py", line 87, in manager_method
    return getattr(self.get_queryset(), name)(*args, **kwargs)
  File "/home/almalinux/.local/lib/python3.9/site-packages/django/db/models/query.py", line 658, in create
    obj.save(force_insert=True, using=self.db)
  File "/home/almalinux/.local/lib/python3.9/site-packages/django/db/models/base.py", line 814, in save
    self.save_base(
  File "/home/almalinux/.local/lib/python3.9/site-packages/django/db/models/base.py", line 877, in save_base
    updated = self._save_table(
  File "/home/almalinux/.local/lib/python3.9/site-packages/django/db/models/base.py", line 1020, in _save_table
    results = self._do_insert(
  File "/home/almalinux/.local/lib/python3.9/site-packages/django/db/models/base.py", line 1061, in _do_insert
    return manager._insert(
  File "/home/almalinux/.local/lib/python3.9/site-packages/django/db/models/manager.py", line 87, in manager_method
    return getattr(self.get_queryset(), name)(*args, **kwargs)
  File "/home/almalinux/.local/lib/python3.9/site-packages/django/db/models/query.py", line 1805, in _insert
    return query.get_compiler(using=using).execute_sql(returning_fields)
  File "/home/almalinux/.local/lib/python3.9/site-packages/django/db/models/sql/compiler.py", line 1820, in execute_sql
    cursor.execute(sql, params)
  File "/home/almalinux/.local/lib/python3.9/site-packages/django/db/backends/utils.py", line 102, in execute
    return super().execute(sql, params)
  File "/home/almalinux/.local/lib/python3.9/site-packages/django/db/backends/utils.py", line 67, in execute
    return self._execute_with_wrappers(
  File "/home/almalinux/.local/lib/python3.9/site-packages/django/db/backends/utils.py", line 80, in _execute_with_wrappers
    return executor(sql, params, many, context)
  File "/home/almalinux/.local/lib/python3.9/site-packages/django/db/backends/utils.py", line 89, in _execute
    return self.cursor.execute(sql, params)
  File "/home/almalinux/.local/lib/python3.9/site-packages/django/db/utils.py", line 91, in __exit__
    raise dj_exc_value.with_traceback(traceback) from exc_value
  File "/home/almalinux/.local/lib/python3.9/site-packages/django/db/backends/utils.py", line 89, in _execute
    return self.cursor.execute(sql, params)
  File "/home/almalinux/.local/lib/python3.9/site-packages/django/db/backends/mysql/base.py", line 75, in execute
    return self.cursor.execute(query, args)
  File "/home/almalinux/.local/lib/python3.9/site-packages/MySQLdb/cursors.py", line 179, in execute
    res = self._query(mogrified_query)
  File "/home/almalinux/.local/lib/python3.9/site-packages/MySQLdb/cursors.py", line 330, in _query
    db.query(q)
  File "/home/almalinux/.local/lib/python3.9/site-packages/MySQLdb/connections.py", line 255, in query
    _mysql.connection.query(self, query)
django.db.utils.IntegrityError: (1364, "Field 'reason' doesn't have a default value")

The above exception was the direct cause of the following exception:

Traceback (most recent call last):
  File "/home/almalinux/.local/lib/python3.9/site-packages/django/core/handlers/exception.py", line 55, in inner
    response = get_response(request)
  File "/home/almalinux/.local/lib/python3.9/site-packages/django/core/handlers/base.py", line 197, in _get_response
    response = wrapped_callback(request, *callback_args, **callback_kwargs)
  File "/home/almalinux/.local/lib/python3.9/site-packages/django/views/decorators/csrf.py", line 56, in wrapper_view
    return view_func(*args, **kwargs)
  File "/home/almalinux/.local/lib/python3.9/site-packages/rest_framework/viewsets.py", line 125, in view
    return self.dispatch(request, *args, **kwargs)
  File "/home/almalinux/.local/lib/python3.9/site-packages/rest_framework/views.py", line 509, in dispatch
    response = self.handle_exception(exc)
  File "/home/almalinux/.local/lib/python3.9/site-packages/rest_framework/views.py", line 469, in handle_exception
    self.raise_uncaught_exception(exc)
  File "/home/almalinux/.local/lib/python3.9/site-packages/rest_framework/views.py", line 480, in raise_uncaught_exception
    raise exc
  File "/home/almalinux/.local/lib/python3.9/site-packages/rest_framework/views.py", line 506, in dispatch
    response = handler(request, *args, **kwargs)
  File "/home/almalinux/.local/lib/python3.9/site-packages/rest_framework/mixins.py", line 19, in create
    self.perform_create(serializer)
  File "/srv/casaaustin/api-casa-austin/src/apps/reservation/views.py", line 233, in perform_create
    instance.save()
  File "/srv/casaaustin/api-casa-austin/src/apps/reservation/models.py", line 140, in save
    super().save(*args, **kwargs)
  File "/home/almalinux/.local/lib/python3.9/site-packages/django/db/models/base.py", line 814, in save
    self.save_base(
  File "/home/almalinux/.local/lib/python3.9/site-packages/django/db/models/base.py", line 861, in save_base
    pre_save.send(
  File "/home/almalinux/.local/lib/python3.9/site-packages/django/dispatch/dispatcher.py", line 176, in send
    return [
  File "/home/almalinux/.local/lib/python3.9/site-packages/django/dispatch/dispatcher.py", line 177, in <listcomp>
    (receiver, receiver(signal=self, sender=sender, **named))
  File "/srv/casaaustin/api-casa-austin/src/apps/reservation/signals.py", line 1158, in reservation_pre_save_handler
    original = Reservation.objects.get(pk=instance.pk)
  File "/home/almalinux/.local/lib/python3.9/site-packages/django/db/models/manager.py", line 87, in manager_method
    return getattr(self.get_queryset(), name)(*args, **kwargs)
  File "/home/almalinux/.local/lib/python3.9/site-packages/django/db/models/query.py", line 633, in get
    num = len(clone)
  File "/home/almalinux/.local/lib/python3.9/site-packages/django/db/models/query.py", line 380, in __len__
    self._fetch_all()
  File "/home/almalinux/.local/lib/python3.9/site-packages/django/db/models/query.py", line 1881, in _fetch_all
    self._result_cache = list(self._iterable_class(self))
  File "/home/almalinux/.local/lib/python3.9/site-packages/django/db/models/query.py", line 91, in __iter__
    results = compiler.execute_sql(
  File "/home/almalinux/.local/lib/python3.9/site-packages/django/db/models/sql/compiler.py", line 1560, in execute_sql
    cursor.execute(sql, params)
  File "/home/almalinux/.local/lib/python3.9/site-packages/django/db/backends/utils.py", line 102, in execute
    return super().execute(sql, params)
  File "/home/almalinux/.local/lib/python3.9/site-packages/django/db/backends/utils.py", line 67, in execute
    return self._execute_with_wrappers(
  File "/home/almalinux/.local/lib/python3.9/site-packages/django/db/backends/utils.py", line 80, in _execute_with_wrappers
    return executor(sql, params, many, context)
  File "/home/almalinux/.local/lib/python3.9/site-packages/django/db/backends/utils.py", line 83, in _execute
    self.db.validate_no_broken_transaction()
  File "/home/almalinux/.local/lib/python3.9/site-packages/django/db/backends/base/base.py", line 531, in validate_no_broken_transaction
    raise TransactionManagementError(
django.db.transaction.TransactionManagementError: An error occurred in the current transaction. You can't execute queries until the end of the 'atomic' block.
ERROR 2025-09-21 09:06:13,307 log 1254915 140585264379712 Internal Server Error: /api/v1/reservations/
Traceback (most recent call last):
  File "/home/almalinux/.local/lib/python3.9/site-packages/django/db/backends/utils.py", line 89, in _execute
    return self.cursor.execute(sql, params)
  File "/home/almalinux/.local/lib/python3.9/site-packages/django/db/backends/mysql/base.py", line 75, in execute
    return self.cursor.execute(query, args)
  File "/home/almalinux/.local/lib/python3.9/site-packages/MySQLdb/cursors.py", line 179, in execute
    res = self._query(mogrified_query)
  File "/home/almalinux/.local/lib/python3.9/site-packages/MySQLdb/cursors.py", line 330, in _query
    db.query(q)
  File "/home/almalinux/.local/lib/python3.9/site-packages/MySQLdb/connections.py", line 255, in query
    _mysql.connection.query(self, query)
MySQLdb.IntegrityError: (1364, "Field 'reason' doesn't have a default value")

The above exception was the direct cause of the following exception:

Traceback (most recent call last):
  File "/srv/casaaustin/api-casa-austin/src/apps/reservation/signals.py", line 829, in reservation_post_save_handler
    activity = ActivityFeed.create_activity(
  File "/srv/casaaustin/api-casa-austin/src/apps/events/models.py", line 645, in create_activity
    return cls.objects.create(
  File "/home/almalinux/.local/lib/python3.9/site-packages/django/db/models/manager.py", line 87, in manager_method
    return getattr(self.get_queryset(), name)(*args, **kwargs)
  File "/home/almalinux/.local/lib/python3.9/site-packages/django/db/models/query.py", line 658, in create
    obj.save(force_insert=True, using=self.db)
  File "/home/almalinux/.local/lib/python3.9/site-packages/django/db/models/base.py", line 814, in save
    self.save_base(
  File "/home/almalinux/.local/lib/python3.9/site-packages/django/db/models/base.py", line 877, in save_base
    updated = self._save_table(
  File "/home/almalinux/.local/lib/python3.9/site-packages/django/db/models/base.py", line 1020, in _save_table
    results = self._do_insert(
  File "/home/almalinux/.local/lib/python3.9/site-packages/django/db/models/base.py", line 1061, in _do_insert
    return manager._insert(
  File "/home/almalinux/.local/lib/python3.9/site-packages/django/db/models/manager.py", line 87, in manager_method
    return getattr(self.get_queryset(), name)(*args, **kwargs)
  File "/home/almalinux/.local/lib/python3.9/site-packages/django/db/models/query.py", line 1805, in _insert
    return query.get_compiler(using=using).execute_sql(returning_fields)
  File "/home/almalinux/.local/lib/python3.9/site-packages/django/db/models/sql/compiler.py", line 1820, in execute_sql
    cursor.execute(sql, params)
  File "/home/almalinux/.local/lib/python3.9/site-packages/django/db/backends/utils.py", line 102, in execute
    return super().execute(sql, params)
  File "/home/almalinux/.local/lib/python3.9/site-packages/django/db/backends/utils.py", line 67, in execute
    return self._execute_with_wrappers(
  File "/home/almalinux/.local/lib/python3.9/site-packages/django/db/backends/utils.py", line 80, in _execute_with_wrappers
    return executor(sql, params, many, context)
  File "/home/almalinux/.local/lib/python3.9/site-packages/django/db/backends/utils.py", line 89, in _execute
    return self.cursor.execute(sql, params)
  File "/home/almalinux/.local/lib/python3.9/site-packages/django/db/utils.py", line 91, in __exit__
    raise dj_exc_value.with_traceback(traceback) from exc_value
  File "/home/almalinux/.local/lib/python3.9/site-packages/django/db/backends/utils.py", line 89, in _execute
    return self.cursor.execute(sql, params)
  File "/home/almalinux/.local/lib/python3.9/site-packages/django/db/backends/mysql/base.py", line 75, in execute
    return self.cursor.execute(query, args)
  File "/home/almalinux/.local/lib/python3.9/site-packages/MySQLdb/cursors.py", line 179, in execute
    res = self._query(mogrified_query)
  File "/home/almalinux/.local/lib/python3.9/site-packages/MySQLdb/cursors.py", line 330, in _query
    db.query(q)
  File "/home/almalinux/.local/lib/python3.9/site-packages/MySQLdb/connections.py", line 255, in query
    _mysql.connection.query(self, query)
django.db.utils.IntegrityError: (1364, "Field 'reason' doesn't have a default value")

The above exception was the direct cause of the following exception:

Traceback (most recent call last):
  File "/home/almalinux/.local/lib/python3.9/site-packages/django/core/handlers/exception.py", line 55, in inner
    response = get_response(request)
  File "/home/almalinux/.local/lib/python3.9/site-packages/django/core/handlers/base.py", line 197, in _get_response
    response = wrapped_callback(request, *callback_args, **callback_kwargs)
  File "/home/almalinux/.local/lib/python3.9/site-packages/django/views/decorators/csrf.py", line 56, in wrapper_view
    return view_func(*args, **kwargs)
  File "/home/almalinux/.local/lib/python3.9/site-packages/rest_framework/viewsets.py", line 125, in view
    return self.dispatch(request, *args, **kwargs)
  File "/home/almalinux/.local/lib/python3.9/site-packages/rest_framework/views.py", line 509, in dispatch
    response = self.handle_exception(exc)
  File "/home/almalinux/.local/lib/python3.9/site-packages/rest_framework/views.py", line 469, in handle_exception
    self.raise_uncaught_exception(exc)
  File "/home/almalinux/.local/lib/python3.9/site-packages/rest_framework/views.py", line 480, in raise_uncaught_exception
    raise exc
  File "/home/almalinux/.local/lib/python3.9/site-packages/rest_framework/views.py", line 506, in dispatch
    response = handler(request, *args, **kwargs)
  File "/home/almalinux/.local/lib/python3.9/site-packages/rest_framework/mixins.py", line 19, in create
    self.perform_create(serializer)
  File "/srv/casaaustin/api-casa-austin/src/apps/reservation/views.py", line 233, in perform_create
    instance.save()
  File "/srv/casaaustin/api-casa-austin/src/apps/reservation/models.py", line 140, in save
    super().save(*args, **kwargs)
  File "/home/almalinux/.local/lib/python3.9/site-packages/django/db/models/base.py", line 814, in save
    self.save_base(
  File "/home/almalinux/.local/lib/python3.9/site-packages/django/db/models/base.py", line 861, in save_base
    pre_save.send(
  File "/home/almalinux/.local/lib/python3.9/site-packages/django/dispatch/dispatcher.py", line 176, in send
    return [
  File "/home/almalinux/.local/lib/python3.9/site-packages/django/dispatch/dispatcher.py", line 177, in <listcomp>
    (receiver, receiver(signal=self, sender=sender, **named))
  File "/srv/casaaustin/api-casa-austin/src/apps/reservation/signals.py", line 1158, in reservation_pre_save_handler
    original = Reservation.objects.get(pk=instance.pk)
  File "/home/almalinux/.local/lib/python3.9/site-packages/django/db/models/manager.py", line 87, in manager_method
    return getattr(self.get_queryset(), name)(*args, **kwargs)
  File "/home/almalinux/.local/lib/python3.9/site-packages/django/db/models/query.py", line 633, in get
    num = len(clone)
  File "/home/almalinux/.local/lib/python3.9/site-packages/django/db/models/query.py", line 380, in __len__
    self._fetch_all()
  File "/home/almalinux/.local/lib/python3.9/site-packages/django/db/models/query.py", line 1881, in _fetch_all
    self._result_cache = list(self._iterable_class(self))
  File "/home/almalinux/.local/lib/python3.9/site-packages/django/db/models/query.py", line 91, in __iter__
    results = compiler.execute_sql(
  File "/home/almalinux/.local/lib/python3.9/site-packages/django/db/models/sql/compiler.py", line 1560, in execute_sql
    cursor.execute(sql, params)
  File "/home/almalinux/.local/lib/python3.9/site-packages/django/db/backends/utils.py", line 102, in execute
    return super().execute(sql, params)
  File "/home/almalinux/.local/lib/python3.9/site-packages/django/db/backends/utils.py", line 67, in execute
    return self._execute_with_wrappers(
  File "/home/almalinux/.local/lib/python3.9/site-packages/django/db/backends/utils.py", line 80, in _execute_with_wrappers
    return executor(sql, params, many, context)
  File "/home/almalinux/.local/lib/python3.9/site-packages/django/db/backends/utils.py", line 83, in _execute
    self.db.validate_no_broken_transaction()
  File "/home/almalinux/.local/lib/python3.9/site-packages/django/db/backends/base/base.py", line 531, in validate_no_broken_transaction
    raise TransactionManagementError(
django.db.transaction.TransactionManagementError: An error occurred in the current transaction. You can't execute queries until the end of the 'atomic' block.