(venv-py311) ➜  api-casa-austin git:(main) ✗ python src/manage.py check
Traceback (most recent call last):
  File "/srv/casaaustin/api-casa-austin/venv-py311/lib64/python3.11/site-packages/django/db/backends/mysql/base.py", line 15, in <module>
    import MySQLdb as Database
ModuleNotFoundError: No module named 'MySQLdb'

The above exception was the direct cause of the following exception:

Traceback (most recent call last):
  File "/srv/casaaustin/api-casa-austin/src/manage.py", line 22, in <module>
    main()
  File "/srv/casaaustin/api-casa-austin/src/manage.py", line 18, in main
    execute_from_command_line(sys.argv)
  File "/srv/casaaustin/api-casa-austin/venv-py311/lib64/python3.11/site-packages/django/core/management/__init__.py", line 442, in execute_from_command_line
    utility.execute()
  File "/srv/casaaustin/api-casa-austin/venv-py311/lib64/python3.11/site-packages/django/core/management/__init__.py", line 416, in execute
    django.setup()
  File "/srv/casaaustin/api-casa-austin/venv-py311/lib64/python3.11/site-packages/django/__init__.py", line 24, in setup
    apps.populate(settings.INSTALLED_APPS)
  File "/srv/casaaustin/api-casa-austin/venv-py311/lib64/python3.11/site-packages/django/apps/registry.py", line 116, in populate
    app_config.import_models()
  File "/srv/casaaustin/api-casa-austin/venv-py311/lib64/python3.11/site-packages/django/apps/config.py", line 269, in import_models
    self.models_module = import_module(models_module_name)
                         ^^^^^^^^^^^^^^^^^^^^^^^^^^^^^^^^^
  File "/usr/lib64/python3.11/importlib/__init__.py", line 126, in import_module
    return _bootstrap._gcd_import(name[level:], package, level)
           ^^^^^^^^^^^^^^^^^^^^^^^^^^^^^^^^^^^^^^^^^^^^^^^^^^^^
  File "<frozen importlib._bootstrap>", line 1204, in _gcd_import
  File "<frozen importlib._bootstrap>", line 1176, in _find_and_load
  File "<frozen importlib._bootstrap>", line 1147, in _find_and_load_unlocked
  File "<frozen importlib._bootstrap>", line 690, in _load_unlocked
  File "<frozen importlib._bootstrap_external>", line 940, in exec_module
  File "<frozen importlib._bootstrap>", line 241, in _call_with_frames_removed
  File "/srv/casaaustin/api-casa-austin/venv-py311/lib64/python3.11/site-packages/django/contrib/auth/models.py", line 3, in <module>
    from django.contrib.auth.base_user import AbstractBaseUser, BaseUserManager
  File "/srv/casaaustin/api-casa-austin/venv-py311/lib64/python3.11/site-packages/django/contrib/auth/base_user.py", line 57, in <module>
    class AbstractBaseUser(models.Model):
  File "/srv/casaaustin/api-casa-austin/venv-py311/lib64/python3.11/site-packages/django/db/models/base.py", line 143, in __new__
    new_class.add_to_class("_meta", Options(meta, app_label))
  File "/srv/casaaustin/api-casa-austin/venv-py311/lib64/python3.11/site-packages/django/db/models/base.py", line 371, in add_to_class
    value.contribute_to_class(cls, name)
  File "/srv/casaaustin/api-casa-austin/venv-py311/lib64/python3.11/site-packages/django/db/models/options.py", line 243, in contribute_to_class
    self.db_table, connection.ops.max_name_length()
                   ^^^^^^^^^^^^^^
  File "/srv/casaaustin/api-casa-austin/venv-py311/lib64/python3.11/site-packages/django/utils/connection.py", line 15, in __getattr__
    return getattr(self._connections[self._alias], item)
                   ~~~~~~~~~~~~~~~~~^^^^^^^^^^^^^
  File "/srv/casaaustin/api-casa-austin/venv-py311/lib64/python3.11/site-packages/django/utils/connection.py", line 62, in __getitem__
    conn = self.create_connection(alias)
           ^^^^^^^^^^^^^^^^^^^^^^^^^^^^^
  File "/srv/casaaustin/api-casa-austin/venv-py311/lib64/python3.11/site-packages/django/db/utils.py", line 193, in create_connection
    backend = load_backend(db["ENGINE"])
              ^^^^^^^^^^^^^^^^^^^^^^^^^^
  File "/srv/casaaustin/api-casa-austin/venv-py311/lib64/python3.11/site-packages/django/db/utils.py", line 113, in load_backend
    return import_module("%s.base" % backend_name)
           ^^^^^^^^^^^^^^^^^^^^^^^^^^^^^^^^^^^^^^^
  File "/usr/lib64/python3.11/importlib/__init__.py", line 126, in import_module
    return _bootstrap._gcd_import(name[level:], package, level)
           ^^^^^^^^^^^^^^^^^^^^^^^^^^^^^^^^^^^^^^^^^^^^^^^^^^^^
  File "/srv/casaaustin/api-casa-austin/venv-py311/lib64/python3.11/site-packages/django/db/backends/mysql/base.py", line 17, in <module>
    raise ImproperlyConfigured(
django.core.exceptions.ImproperlyConfigured: Error loading MySQLdb module.
Did you install mysqlclient?