INFO 2025-09-06 18:16:54,718 whatsapp_service 1382135 139935162550080 WhatsApp pago aprobado enviado exitosamente a 51985941893. Response: {'messaging_product': 'whatsapp', 'contacts': [{'input': '51985941893', 'wa_id': '51985941893'}], 'messages': [{'id': 'wamid.HBgLNTE5ODU5NDE4OTMVAgARGBIwODkxMDMxN0M5QjUzM0ExMTcA', 'message_status': 'accepted'}]}
INFO 2025-09-06 18:16:54,719 signals 1382135 139935162550080 WhatsApp de pago aprobado enviado exitosamente para reserva d42d6405-7976-4f71-8da7-9afb2b360a06
DEBUG 2025-09-06 18:16:54,720 signals 1382135 139935162550080 Verificando logros para cliente 11296f60-9b26-46c9-a836-e964f2a83fa6 después de actualizar reserva d42d6405-7976-4f71-8da7-9afb2b360a06
DEBUG 2025-09-06 18:16:54,724 points_signals 1382135 139935162550080 🔄 Cliente 11296f60-9b26-46c9-a836-e964f2a83fa6 ya tiene el logro 'Curioso'
ERROR 2025-09-06 18:16:54,727 points_signals 1382135 139935162550080 ❌ Error verificando logros para cliente 11296f60-9b26-46c9-a836-e964f2a83fa6: (1062, "Duplicate entry '11296f609b2646c9a836e964f2a83fa6-6d35cc334685421794279b3dbb7d310' for key 'clients_clientachievement.clients_clientachievement_client_id_achievement_id_3afb6388_uniq'")
DEBUG 2025-09-06 18:16:54,727 signals 1382135 139935162550080 Verificando logros para cliente 11296f60-9b26-46c9-a836-e964f2a83fa6 después de actualizar reserva d42d6405-7976-4f71-8da7-9afb2b360a06
ERROR 2025-09-06 18:16:54,728 points_signals 1382135 139935162550080 ❌ Error verificando logros para cliente 11296f60-9b26-46c9-a836-e964f2a83fa6: An error occurred in the current transaction. You can't execute queries until the end of the 'atomic' block.
Internal Server Error: /api/v1/reservations/d42d6405-7976-4f71-8da7-9afb2b360a06/
Traceback (most recent call last):
  File "/home/almalinux/.local/lib/python3.9/site-packages/django/db/backends/utils.py", line 89, in _execute
    return self.cursor.execute(sql, params)
  File "/home/almalinux/.local/lib/python3.9/site-packages/django/db/backends/mysql/base.py", line 75, in execute
    return self.cursor.execute(query, args)
  File "/home/almalinux/.local/lib/python3.9/site-packages/MySQLdb/cursors.py", line 179, in execute
    res = self._query(mogrified_query)
  File "/home/almalinux/.local/lib/python3.9/site-packages/MySQLdb/cursors.py", line 330, in _query
    db.query(q)
  File "/home/almalinux/.local/lib/python3.9/site-packages/MySQLdb/connections.py", line 261, in query
    _mysql.connection.query(self, query)
MySQLdb.IntegrityError: (1062, "Duplicate entry '11296f609b2646c9a836e964f2a83fa6-6d35cc334685421794279b3dbb7d310' for key 'clients_clientachievement.clients_clientachievement_client_id_achievement_id_3afb6388_uniq'")

The above exception was the direct cause of the following exception:

Traceback (most recent call last):
  File "/srv/casaaustin/api-casa-austin/src/apps/reservation/points_signals.py", line 180, in check_and_assign_achievements
    new_achievement = ClientAchievement.objects.create(
  File "/home/almalinux/.local/lib/python3.9/site-packages/django/db/models/manager.py", line 87, in manager_method
    return getattr(self.get_queryset(), name)(*args, **kwargs)
  File "/home/almalinux/.local/lib/python3.9/site-packages/django/db/models/query.py", line 658, in create
    obj.save(force_insert=True, using=self.db)
  File "/home/almalinux/.local/lib/python3.9/site-packages/django/db/models/base.py", line 814, in save
    self.save_base(
  File "/home/almalinux/.local/lib/python3.9/site-packages/django/db/models/base.py", line 877, in save_base
    updated = self._save_table(
  File "/home/almalinux/.local/lib/python3.9/site-packages/django/db/models/base.py", line 1020, in _save_table
    results = self._do_insert(
  File "/home/almalinux/.local/lib/python3.9/site-packages/django/db/models/base.py", line 1061, in _do_insert
    return manager._insert(
  File "/home/almalinux/.local/lib/python3.9/site-packages/django/db/models/manager.py", line 87, in manager_method
    return getattr(self.get_queryset(), name)(*args, **kwargs)
  File "/home/almalinux/.local/lib/python3.9/site-packages/django/db/models/query.py", line 1805, in _insert
    return query.get_compiler(using=using).execute_sql(returning_fields)
  File "/home/almalinux/.local/lib/python3.9/site-packages/django/db/models/sql/compiler.py", line 1822, in execute_sql
    cursor.execute(sql, params)
  File "/home/almalinux/.local/lib/python3.9/site-packages/django/db/backends/utils.py", line 102, in execute
    return super().execute(sql, params)
  File "/home/almalinux/.local/lib/python3.9/site-packages/django/db/backends/utils.py", line 67, in execute
    return self._execute_with_wrappers(
  File "/home/almalinux/.local/lib/python3.9/site-packages/django/db/backends/utils.py", line 80, in _execute_with_wrappers
    return executor(sql, params, many, context)
  File "/home/almalinux/.local/lib/python3.9/site-packages/django/db/backends/utils.py", line 89, in _execute
    return self.cursor.execute(sql, params)
  File "/home/almalinux/.local/lib/python3.9/site-packages/django/db/utils.py", line 91, in __exit__
    raise dj_exc_value.with_traceback(traceback) from exc_value
  File "/home/almalinux/.local/lib/python3.9/site-packages/django/db/backends/utils.py", line 89, in _execute
    return self.cursor.execute(sql, params)
  File "/home/almalinux/.local/lib/python3.9/site-packages/django/db/backends/mysql/base.py", line 75, in execute
    return self.cursor.execute(query, args)
  File "/home/almalinux/.local/lib/python3.9/site-packages/MySQLdb/cursors.py", line 179, in execute
    res = self._query(mogrified_query)
  File "/home/almalinux/.local/lib/python3.9/site-packages/MySQLdb/cursors.py", line 330, in _query
    db.query(q)
  File "/home/almalinux/.local/lib/python3.9/site-packages/MySQLdb/connections.py", line 261, in query
    _mysql.connection.query(self, query)
django.db.utils.IntegrityError: (1062, "Duplicate entry '11296f609b2646c9a836e964f2a83fa6-6d35cc334685421794279b3dbb7d310' for key 'clients_clientachievement.clients_clientachievement_client_id_achievement_id_3afb6388_uniq'")

The above exception was the direct cause of the following exception:

Traceback (most recent call last):
  File "/home/almalinux/.local/lib/python3.9/site-packages/django/core/handlers/exception.py", line 55, in inner
    response = get_response(request)
  File "/home/almalinux/.local/lib/python3.9/site-packages/django/core/handlers/base.py", line 197, in _get_response
    response = wrapped_callback(request, *callback_args, **callback_kwargs)
  File "/home/almalinux/.local/lib/python3.9/site-packages/django/views/decorators/csrf.py", line 56, in wrapper_view
    return view_func(*args, **kwargs)
  File "/home/almalinux/.local/lib/python3.9/site-packages/rest_framework/viewsets.py", line 124, in view
    return self.dispatch(request, *args, **kwargs)
  File "/home/almalinux/.local/lib/python3.9/site-packages/rest_framework/views.py", line 509, in dispatch
    response = self.handle_exception(exc)
  File "/home/almalinux/.local/lib/python3.9/site-packages/rest_framework/views.py", line 469, in handle_exception
    self.raise_uncaught_exception(exc)
  File "/home/almalinux/.local/lib/python3.9/site-packages/rest_framework/views.py", line 480, in raise_uncaught_exception
    raise exc
  File "/home/almalinux/.local/lib/python3.9/site-packages/rest_framework/views.py", line 506, in dispatch
    response = handler(request, *args, **kwargs)
  File "/srv/casaaustin/api-casa-austin/src/apps/reservation/views.py", line 292, in partial_update
    instance.save()
  File "/srv/casaaustin/api-casa-austin/src/apps/reservation/models.py", line 124, in save
    super().save(*args, **kwargs)
  File "/home/almalinux/.local/lib/python3.9/site-packages/django/db/models/base.py", line 814, in save
    self.save_base(
  File "/home/almalinux/.local/lib/python3.9/site-packages/django/db/models/base.py", line 877, in save_base
    updated = self._save_table(
  File "/home/almalinux/.local/lib/python3.9/site-packages/django/db/models/base.py", line 990, in _save_table
    updated = self._do_update(
  File "/home/almalinux/.local/lib/python3.9/site-packages/django/db/models/base.py", line 1054, in _do_update
    return filtered._update(values) > 0
  File "/home/almalinux/.local/lib/python3.9/site-packages/django/db/models/query.py", line 1231, in _update
    return query.get_compiler(self.db).execute_sql(CURSOR)
  File "/home/almalinux/.local/lib/python3.9/site-packages/django/db/models/sql/compiler.py", line 1984, in execute_sql
    cursor = super().execute_sql(result_type)
  File "/home/almalinux/.local/lib/python3.9/site-packages/django/db/models/sql/compiler.py", line 1562, in execute_sql
    cursor.execute(sql, params)
  File "/home/almalinux/.local/lib/python3.9/site-packages/django/db/backends/utils.py", line 102, in execute
    return super().execute(sql, params)
  File "/home/almalinux/.local/lib/python3.9/site-packages/django/db/backends/utils.py", line 67, in execute
    return self._execute_with_wrappers(
  File "/home/almalinux/.local/lib/python3.9/site-packages/django/db/backends/utils.py", line 80, in _execute_with_wrappers
    return executor(sql, params, many, context)
  File "/home/almalinux/.local/lib/python3.9/site-packages/django/db/backends/utils.py", line 83, in _execute
    self.db.validate_no_broken_transaction()
  File "/home/almalinux/.local/lib/python3.9/site-packages/django/db/backends/base/base.py", line 531, in validate_no_broken_transaction
    raise TransactionManagementError(
django.db.transaction.TransactionManagementError: An error occurred in the current transaction. You can't execute queries until the end of the 'atomic' block.
ERROR 2025-09-06 18:16:54,902 log 1382135 139935162550080 Internal Server Error: /api/v1/reservations/d42d6405-7976-4f71-8da7-9afb2b360a06/
Traceback (most recent call last):
  File "/home/almalinux/.local/lib/python3.9/site-packages/django/db/backends/utils.py", line 89, in _execute
    return self.cursor.execute(sql, params)
  File "/home/almalinux/.local/lib/python3.9/site-packages/django/db/backends/mysql/base.py", line 75, in execute
    return self.cursor.execute(query, args)
  File "/home/almalinux/.local/lib/python3.9/site-packages/MySQLdb/cursors.py", line 179, in execute
    res = self._query(mogrified_query)
  File "/home/almalinux/.local/lib/python3.9/site-packages/MySQLdb/cursors.py", line 330, in _query
    db.query(q)
  File "/home/almalinux/.local/lib/python3.9/site-packages/MySQLdb/connections.py", line 261, in query
    _mysql.connection.query(self, query)
MySQLdb.IntegrityError: (1062, "Duplicate entry '11296f609b2646c9a836e964f2a83fa6-6d35cc334685421794279b3dbb7d310' for key 'clients_clientachievement.clients_clientachievement_client_id_achievement_id_3afb6388_uniq'")

The above exception was the direct cause of the following exception:

Traceback (most recent call last):
  File "/srv/casaaustin/api-casa-austin/src/apps/reservation/points_signals.py", line 180, in check_and_assign_achievements
    new_achievement = ClientAchievement.objects.create(
  File "/home/almalinux/.local/lib/python3.9/site-packages/django/db/models/manager.py", line 87, in manager_method
    return getattr(self.get_queryset(), name)(*args, **kwargs)
  File "/home/almalinux/.local/lib/python3.9/site-packages/django/db/models/query.py", line 658, in create
    obj.save(force_insert=True, using=self.db)
  File "/home/almalinux/.local/lib/python3.9/site-packages/django/db/models/base.py", line 814, in save
    self.save_base(
  File "/home/almalinux/.local/lib/python3.9/site-packages/django/db/models/base.py", line 877, in save_base
    updated = self._save_table(
  File "/home/almalinux/.local/lib/python3.9/site-packages/django/db/models/base.py", line 1020, in _save_table
    results = self._do_insert(
  File "/home/almalinux/.local/lib/python3.9/site-packages/django/db/models/base.py", line 1061, in _do_insert
    return manager._insert(
  File "/home/almalinux/.local/lib/python3.9/site-packages/django/db/models/manager.py", line 87, in manager_method
    return getattr(self.get_queryset(), name)(*args, **kwargs)
  File "/home/almalinux/.local/lib/python3.9/site-packages/django/db/models/query.py", line 1805, in _insert
    return query.get_compiler(using=using).execute_sql(returning_fields)
  File "/home/almalinux/.local/lib/python3.9/site-packages/django/db/models/sql/compiler.py", line 1822, in execute_sql
    cursor.execute(sql, params)
  File "/home/almalinux/.local/lib/python3.9/site-packages/django/db/backends/utils.py", line 102, in execute
    return super().execute(sql, params)
  File "/home/almalinux/.local/lib/python3.9/site-packages/django/db/backends/utils.py", line 67, in execute
    return self._execute_with_wrappers(
  File "/home/almalinux/.local/lib/python3.9/site-packages/django/db/backends/utils.py", line 80, in _execute_with_wrappers
    return executor(sql, params, many, context)
  File "/home/almalinux/.local/lib/python3.9/site-packages/django/db/backends/utils.py", line 89, in _execute
    return self.cursor.execute(sql, params)
  File "/home/almalinux/.local/lib/python3.9/site-packages/django/db/utils.py", line 91, in __exit__
    raise dj_exc_value.with_traceback(traceback) from exc_value
  File "/home/almalinux/.local/lib/python3.9/site-packages/django/db/backends/utils.py", line 89, in _execute
    return self.cursor.execute(sql, params)
  File "/home/almalinux/.local/lib/python3.9/site-packages/django/db/backends/mysql/base.py", line 75, in execute
    return self.cursor.execute(query, args)
  File "/home/almalinux/.local/lib/python3.9/site-packages/MySQLdb/cursors.py", line 179, in execute
    res = self._query(mogrified_query)
  File "/home/almalinux/.local/lib/python3.9/site-packages/MySQLdb/cursors.py", line 330, in _query
    db.query(q)
  File "/home/almalinux/.local/lib/python3.9/site-packages/MySQLdb/connections.py", line 261, in query
    _mysql.connection.query(self, query)
django.db.utils.IntegrityError: (1062, "Duplicate entry '11296f609b2646c9a836e964f2a83fa6-6d35cc334685421794279b3dbb7d310' for key 'clients_clientachievement.clients_clientachievement_client_id_achievement_id_3afb6388_uniq'")

The above exception was the direct cause of the following exception:

Traceback (most recent call last):
  File "/home/almalinux/.local/lib/python3.9/site-packages/django/core/handlers/exception.py", line 55, in inner
    response = get_response(request)
  File "/home/almalinux/.local/lib/python3.9/site-packages/django/core/handlers/base.py", line 197, in _get_response
    response = wrapped_callback(request, *callback_args, **callback_kwargs)
  File "/home/almalinux/.local/lib/python3.9/site-packages/django/views/decorators/csrf.py", line 56, in wrapper_view
    return view_func(*args, **kwargs)
  File "/home/almalinux/.local/lib/python3.9/site-packages/rest_framework/viewsets.py", line 124, in view
    return self.dispatch(request, *args, **kwargs)
  File "/home/almalinux/.local/lib/python3.9/site-packages/rest_framework/views.py", line 509, in dispatch
    response = self.handle_exception(exc)
  File "/home/almalinux/.local/lib/python3.9/site-packages/rest_framework/views.py", line 469, in handle_exception
    self.raise_uncaught_exception(exc)
  File "/home/almalinux/.local/lib/python3.9/site-packages/rest_framework/views.py", line 480, in raise_uncaught_exception
    raise exc
  File "/home/almalinux/.local/lib/python3.9/site-packages/rest_framework/views.py", line 506, in dispatch
    response = handler(request, *args, **kwargs)
  File "/srv/casaaustin/api-casa-austin/src/apps/reservation/views.py", line 292, in partial_update
    instance.save()
  File "/srv/casaaustin/api-casa-austin/src/apps/reservation/models.py", line 124, in save
    super().save(*args, **kwargs)
  File "/home/almalinux/.local/lib/python3.9/site-packages/django/db/models/base.py", line 814, in save
    self.save_base(
  File "/home/almalinux/.local/lib/python3.9/site-packages/django/db/models/base.py", line 877, in save_base
    updated = self._save_table(
  File "/home/almalinux/.local/lib/python3.9/site-packages/django/db/models/base.py", line 990, in _save_table
    updated = self._do_update(
  File "/home/almalinux/.local/lib/python3.9/site-packages/django/db/models/base.py", line 1054, in _do_update
    return filtered._update(values) > 0
  File "/home/almalinux/.local/lib/python3.9/site-packages/django/db/models/query.py", line 1231, in _update
    return query.get_compiler(self.db).execute_sql(CURSOR)
  File "/home/almalinux/.local/lib/python3.9/site-packages/django/db/models/sql/compiler.py", line 1984, in execute_sql
    cursor = super().execute_sql(result_type)
  File "/home/almalinux/.local/lib/python3.9/site-packages/django/db/models/sql/compiler.py", line 1562, in execute_sql
    cursor.execute(sql, params)
  File "/home/almalinux/.local/lib/python3.9/site-packages/django/db/backends/utils.py", line 102, in execute
    return super().execute(sql, params)
  File "/home/almalinux/.local/lib/python3.9/site-packages/django/db/backends/utils.py", line 67, in execute
    return self._execute_with_wrappers(
  File "/home/almalinux/.local/lib/python3.9/site-packages/django/db/backends/utils.py", line 80, in _execute_with_wrappers
    return executor(sql, params, many, context)
  File "/home/almalinux/.local/lib/python3.9/site-packages/django/db/backends/utils.py", line 83, in _execute
    self.db.validate_no_broken_transaction()
  File "/home/almalinux/.local/lib/python3.9/site-packages/django/db/backends/base/base.py", line 531, in validate_no_broken_transaction
    raise TransactionManagementError(
django.db.transaction.TransactionManagementError: An error occurred in the current transaction. You can't execute queries until the end of the 'atomic' block.
