[2025-09-06 17:59:12 -0500] [1380854] [INFO] Starting gunicorn 21.2.0
[2025-09-06 17:59:12 -0500] [1380854] [INFO] Listening at: http://0.0.0.0:8000 (1380854)
[2025-09-06 17:59:12 -0500] [1380854] [INFO] Using worker: sync
[2025-09-06 17:59:12 -0500] [1380855] [INFO] Booting worker with pid: 1380855
[2025-09-06 17:59:12 -0500] [1380855] [ERROR] Exception in worker process
Traceback (most recent call last):
  File "/home/almalinux/.local/lib/python3.9/site-packages/gunicorn/arbiter.py", line 609, in spawn_worker
    worker.init_process()
  File "/home/almalinux/.local/lib/python3.9/site-packages/gunicorn/workers/base.py", line 134, in init_process
    self.load_wsgi()
  File "/home/almalinux/.local/lib/python3.9/site-packages/gunicorn/workers/base.py", line 146, in load_wsgi
    self.wsgi = self.app.wsgi()
  File "/home/almalinux/.local/lib/python3.9/site-packages/gunicorn/app/base.py", line 67, in wsgi
    self.callable = self.load()
  File "/home/almalinux/.local/lib/python3.9/site-packages/gunicorn/app/wsgiapp.py", line 58, in load
    return self.load_wsgiapp()
  File "/home/almalinux/.local/lib/python3.9/site-packages/gunicorn/app/wsgiapp.py", line 48, in load_wsgiapp
    return util.import_app(self.app_uri)
  File "/home/almalinux/.local/lib/python3.9/site-packages/gunicorn/util.py", line 371, in import_app
    mod = importlib.import_module(module)
  File "/usr/lib64/python3.9/importlib/__init__.py", line 127, in import_module
    return _bootstrap._gcd_import(name[level:], package, level)
  File "<frozen importlib._bootstrap>", line 1030, in _gcd_import
  File "<frozen importlib._bootstrap>", line 1007, in _find_and_load
  File "<frozen importlib._bootstrap>", line 986, in _find_and_load_unlocked
  File "<frozen importlib._bootstrap>", line 680, in _load_unlocked
  File "<frozen importlib._bootstrap_external>", line 850, in exec_module
  File "<frozen importlib._bootstrap>", line 228, in _call_with_frames_removed
  File "/srv/casaaustin/api-casa-austin/src/config/wsgi.py", line 16, in <module>
    application = get_wsgi_application()
  File "/home/almalinux/.local/lib/python3.9/site-packages/django/core/wsgi.py", line 12, in get_wsgi_application
    django.setup(set_prefix=False)
  File "/home/almalinux/.local/lib/python3.9/site-packages/django/__init__.py", line 19, in setup
    configure_logging(settings.LOGGING_CONFIG, settings.LOGGING)
  File "/home/almalinux/.local/lib/python3.9/site-packages/django/conf/__init__.py", line 102, in __getattr__
    self._setup(name)
  File "/home/almalinux/.local/lib/python3.9/site-packages/django/conf/__init__.py", line 89, in _setup
    self._wrapped = Settings(settings_module)
  File "/home/almalinux/.local/lib/python3.9/site-packages/django/conf/__init__.py", line 217, in __init__
    mod = importlib.import_module(self.SETTINGS_MODULE)
  File "/usr/lib64/python3.9/importlib/__init__.py", line 127, in import_module
    return _bootstrap._gcd_import(name[level:], package, level)
  File "<frozen importlib._bootstrap>", line 1030, in _gcd_import
  File "<frozen importlib._bootstrap>", line 1007, in _find_and_load
  File "<frozen importlib._bootstrap>", line 986, in _find_and_load_unlocked
  File "<frozen importlib._bootstrap>", line 680, in _load_unlocked
  File "<frozen importlib._bootstrap_external>", line 850, in exec_module
  File "<frozen importlib._bootstrap>", line 228, in _call_with_frames_removed
  File "/srv/casaaustin/api-casa-austin/src/config/settings.py", line 12, in <module>
    c
NameError: name 'c' is not defined
[2025-09-06 17:59:12 -0500] [1380855] [INFO] Worker exiting (pid: 1380855)
[2025-09-06 17:59:12 -0500] [1380854] [ERROR] Worker (pid:1380855) exited with code 3
[2025-09-06 17:59:12 -0500] [1380854] [ERROR] Shutting down: Master
[2025-09-06 17:59:12 -0500] [1380854] [ERROR] Reason: Worker failed to boot.