➜  src git:(main) ✗ gunicorn --bind 0.0.0.0:8000 config.wsgi:application
[2025-09-22 05:31:54 -0500] [1556464] [INFO] Starting gunicorn 21.2.0
[2025-09-22 05:31:54 -0500] [1556464] [INFO] Listening at: http://0.0.0.0:8000 (1556464)
[2025-09-22 05:31:54 -0500] [1556464] [INFO] Using worker: sync
[2025-09-22 05:31:54 -0500] [1556465] [INFO] Booting worker with pid: 1556465
Internal Server Error: /api/v1/events/my-registrations/
Traceback (most recent call last):
  File "/home/almalinux/.local/lib/python3.9/site-packages/django/core/handlers/exception.py", line 55, in inner
    response = get_response(request)
  File "/home/almalinux/.local/lib/python3.9/site-packages/django/core/handlers/base.py", line 197, in _get_response
    response = wrapped_callback(request, *callback_args, **callback_kwargs)
  File "/home/almalinux/.local/lib/python3.9/site-packages/django/views/decorators/csrf.py", line 56, in wrapper_view
    return view_func(*args, **kwargs)
  File "/home/almalinux/.local/lib/python3.9/site-packages/django/views/generic/base.py", line 104, in view
    return self.dispatch(request, *args, **kwargs)
  File "/home/almalinux/.local/lib/python3.9/site-packages/rest_framework/views.py", line 509, in dispatch
    response = self.handle_exception(exc)
  File "/home/almalinux/.local/lib/python3.9/site-packages/rest_framework/views.py", line 469, in handle_exception
    self.raise_uncaught_exception(exc)
  File "/home/almalinux/.local/lib/python3.9/site-packages/rest_framework/views.py", line 480, in raise_uncaught_exception
    raise exc
  File "/home/almalinux/.local/lib/python3.9/site-packages/rest_framework/views.py", line 506, in dispatch
    response = handler(request, *args, **kwargs)
  File "/home/almalinux/.local/lib/python3.9/site-packages/rest_framework/generics.py", line 199, in get
    return self.list(request, *args, **kwargs)
  File "/srv/casaaustin/api-casa-austin/src/apps/events/views.py", line 343, in list
    registration_data = EventRegistrationSerializer(registration).data
  File "/home/almalinux/.local/lib/python3.9/site-packages/rest_framework/serializers.py", line 555, in data
    ret = super().data
  File "/home/almalinux/.local/lib/python3.9/site-packages/rest_framework/serializers.py", line 253, in data
    self._data = self.to_representation(self.instance)
  File "/srv/casaaustin/api-casa-austin/src/apps/events/serializers.py", line 126, in to_representation
    representation = super().to_representation(instance)
  File "/home/almalinux/.local/lib/python3.9/site-packages/rest_framework/serializers.py", line 507, in to_representation
    for field in fields:
  File "/home/almalinux/.local/lib/python3.9/site-packages/rest_framework/serializers.py", line 368, in _readable_fields
    for field in self.fields.values():
  File "/home/almalinux/.local/lib/python3.9/site-packages/django/utils/functional.py", line 57, in __get__
    res = instance.__dict__[self.name] = self.func(instance)
  File "/home/almalinux/.local/lib/python3.9/site-packages/rest_framework/serializers.py", line 356, in fields
    for key, value in self.get_fields().items():
  File "/home/almalinux/.local/lib/python3.9/site-packages/rest_framework/serializers.py", line 1052, in get_fields
    field_names = self.get_field_names(declared_fields, info)
  File "/home/almalinux/.local/lib/python3.9/site-packages/rest_framework/serializers.py", line 1148, in get_field_names
    assert field_name in fields, (
AssertionError: The field 'client_name' was declared on serializer EventRegistrationSerializer, but has not been included in the 'fields' option.
ERROR 2025-09-22 05:31:59,991 log 1556465 139800202065728 Internal Server Error: /api/v1/events/my-registrations/
Traceback (most recent call last):
  File "/home/almalinux/.local/lib/python3.9/site-packages/django/core/handlers/exception.py", line 55, in inner
    response = get_response(request)
  File "/home/almalinux/.local/lib/python3.9/site-packages/django/core/handlers/base.py", line 197, in _get_response
    response = wrapped_callback(request, *callback_args, **callback_kwargs)
  File "/home/almalinux/.local/lib/python3.9/site-packages/django/views/decorators/csrf.py", line 56, in wrapper_view
    return view_func(*args, **kwargs)
  File "/home/almalinux/.local/lib/python3.9/site-packages/django/views/generic/base.py", line 104, in view
    return self.dispatch(request, *args, **kwargs)
  File "/home/almalinux/.local/lib/python3.9/site-packages/rest_framework/views.py", line 509, in dispatch
    response = self.handle_exception(exc)
  File "/home/almalinux/.local/lib/python3.9/site-packages/rest_framework/views.py", line 469, in handle_exception
    self.raise_uncaught_exception(exc)
  File "/home/almalinux/.local/lib/python3.9/site-packages/rest_framework/views.py", line 480, in raise_uncaught_exception
    raise exc
  File "/home/almalinux/.local/lib/python3.9/site-packages/rest_framework/views.py", line 506, in dispatch
    response = handler(request, *args, **kwargs)
  File "/home/almalinux/.local/lib/python3.9/site-packages/rest_framework/generics.py", line 199, in get
    return self.list(request, *args, **kwargs)
  File "/srv/casaaustin/api-casa-austin/src/apps/events/views.py", line 343, in list
    registration_data = EventRegistrationSerializer(registration).data
  File "/home/almalinux/.local/lib/python3.9/site-packages/rest_framework/serializers.py", line 555, in data
    ret = super().data
  File "/home/almalinux/.local/lib/python3.9/site-packages/rest_framework/serializers.py", line 253, in data
    self._data = self.to_representation(self.instance)
  File "/srv/casaaustin/api-casa-austin/src/apps/events/serializers.py", line 126, in to_representation
    representation = super().to_representation(instance)
  File "/home/almalinux/.local/lib/python3.9/site-packages/rest_framework/serializers.py", line 507, in to_representation
    for field in fields:
  File "/home/almalinux/.local/lib/python3.9/site-packages/rest_framework/serializers.py", line 368, in _readable_fields
    for field in self.fields.values():
  File "/home/almalinux/.local/lib/python3.9/site-packages/django/utils/functional.py", line 57, in __get__
    res = instance.__dict__[self.name] = self.func(instance)
  File "/home/almalinux/.local/lib/python3.9/site-packages/rest_framework/serializers.py", line 356, in fields
    for key, value in self.get_fields().items():
  File "/home/almalinux/.local/lib/python3.9/site-packages/rest_framework/serializers.py", line 1052, in get_fields
    field_names = self.get_field_names(declared_fields, info)
  File "/home/almalinux/.local/lib/python3.9/site-packages/rest_framework/serializers.py", line 1148, in get_field_names
    assert field_name in fields, (
AssertionError: The field 'client_name' was declared on serializer EventRegistrationSerializer, but has not been included in the 'fields' option.