2025-09-07 16:20:34 -0500] [1428958] [INFO] Starting gunicorn 21.2.0
[2025-09-07 16:20:34 -0500] [1428958] [INFO] Listening at: http://0.0.0.0:8000 (1428958)
[2025-09-07 16:20:34 -0500] [1428958] [INFO] Using worker: sync
[2025-09-07 16:20:34 -0500] [1428959] [INFO] Booting worker with pid: 1428959
[2025-09-07 16:20:40 -0500] [1428959] [ERROR] Error handling request /api/v1/properties/calculate-pricing/?check_in_date=2025-09-24&check_out_date=2025-09-25&guests=2&property_id=573c6650-65a7-4e81-883a-2b910159731b&client_id=405a0119-caba-467c-8f4c-835f45402367&additional_services=6d3d74ed-54a1-422a-b244-582848a169d2
Traceback (most recent call last):
  File "/home/almalinux/.local/lib/python3.9/site-packages/django/core/handlers/exception.py", line 55, in inner
    response = get_response(request)
  File "/home/almalinux/.local/lib/python3.9/site-packages/django/core/handlers/base.py", line 181, in _get_response
    callback, callback_args, callback_kwargs = self.resolve_request(request)
  File "/home/almalinux/.local/lib/python3.9/site-packages/django/core/handlers/base.py", line 313, in resolve_request
    resolver_match = resolver.resolve(request.path_info)
  File "/home/almalinux/.local/lib/python3.9/site-packages/django/urls/resolvers.py", line 663, in resolve
    for pattern in self.url_patterns:
  File "/home/almalinux/.local/lib/python3.9/site-packages/django/utils/functional.py", line 57, in __get__
    res = instance.__dict__[self.name] = self.func(instance)
  File "/home/almalinux/.local/lib/python3.9/site-packages/django/urls/resolvers.py", line 715, in url_patterns
    patterns = getattr(self.urlconf_module, "urlpatterns", self.urlconf_module)
  File "/home/almalinux/.local/lib/python3.9/site-packages/django/utils/functional.py", line 57, in __get__
    res = instance.__dict__[self.name] = self.func(instance)
  File "/home/almalinux/.local/lib/python3.9/site-packages/django/urls/resolvers.py", line 708, in urlconf_module
    return import_module(self.urlconf_name)
  File "/usr/lib64/python3.9/importlib/__init__.py", line 127, in import_module
    return _bootstrap._gcd_import(name[level:], package, level)
  File "<frozen importlib._bootstrap>", line 1030, in _gcd_import
  File "<frozen importlib._bootstrap>", line 1007, in _find_and_load
  File "<frozen importlib._bootstrap>", line 986, in _find_and_load_unlocked
  File "<frozen importlib._bootstrap>", line 680, in _load_unlocked
  File "<frozen importlib._bootstrap_external>", line 850, in exec_module
  File "<frozen importlib._bootstrap>", line 228, in _call_with_frames_removed
  File "/srv/casaaustin/api-casa-austin/src/config/urls.py", line 23, in <module>
    path("api/v1/", include("apps.property.urls")),
  File "/home/almalinux/.local/lib/python3.9/site-packages/django/urls/conf.py", line 38, in include
    urlconf_module = import_module(urlconf_module)
  File "/usr/lib64/python3.9/importlib/__init__.py", line 127, in import_module
    return _bootstrap._gcd_import(name[level:], package, level)
  File "<frozen importlib._bootstrap>", line 1030, in _gcd_import
  File "<frozen importlib._bootstrap>", line 1007, in _find_and_load
  File "<frozen importlib._bootstrap>", line 986, in _find_and_load_unlocked
  File "<frozen importlib._bootstrap>", line 680, in _load_unlocked
  File "<frozen importlib._bootstrap_external>", line 850, in exec_module
  File "<frozen importlib._bootstrap>", line 228, in _call_with_frames_removed
  File "/srv/casaaustin/api-casa-austin/src/apps/property/urls.py", line 1, in <module>
    from .views import (
  File "/srv/casaaustin/api-casa-austin/src/apps/property/views.py", line 3, in <module>
    from django import models
ImportError: cannot import name 'models' from 'django' (/home/almalinux/.local/lib/python3.9/site-packages/django/__init__.py)

During handling of the above exception, another exception occurred:

Traceback (most recent call last):
  File "/home/almalinux/.local/lib/python3.9/site-packages/django/core/handlers/exception.py", line 55, in inner
    response = get_response(request)
  File "/home/almalinux/.local/lib/python3.9/site-packages/django/utils/deprecation.py", line 134, in __call__
    response = response or self.get_response(request)
  File "/home/almalinux/.local/lib/python3.9/site-packages/django/core/handlers/exception.py", line 57, in inner
    response = response_for_exception(request, exc)
  File "/home/almalinux/.local/lib/python3.9/site-packages/django/core/handlers/exception.py", line 140, in response_for_exception
    response = handle_uncaught_exception(
  File "/home/almalinux/.local/lib/python3.9/site-packages/django/core/handlers/exception.py", line 181, in handle_uncaught_exception
    return debug.technical_500_response(request, *exc_info)
  File "/home/almalinux/.local/lib/python3.9/site-packages/django/views/debug.py", line 67, in technical_500_response
    html = reporter.get_traceback_html()
  File "/home/almalinux/.local/lib/python3.9/site-packages/django/views/debug.py", line 410, in get_traceback_html
    c = Context(self.get_traceback_data(), use_l10n=False)
  File "/home/almalinux/.local/lib/python3.9/site-packages/django/views/debug.py", line 393, in get_traceback_data
    c["raising_view_name"] = get_caller(self.request)
  File "/home/almalinux/.local/lib/python3.9/site-packages/django/views/debug.py", line 100, in get_caller
    resolver_match = resolve(request.path)
  File "/home/almalinux/.local/lib/python3.9/site-packages/django/urls/base.py", line 24, in resolve
    return get_resolver(urlconf).resolve(path)
  File "/home/almalinux/.local/lib/python3.9/site-packages/django/urls/resolvers.py", line 663, in resolve
    for pattern in self.url_patterns:
  File "/home/almalinux/.local/lib/python3.9/site-packages/django/utils/functional.py", line 57, in __get__
    res = instance.__dict__[self.name] = self.func(instance)
  File "/home/almalinux/.local/lib/python3.9/site-packages/django/urls/resolvers.py", line 715, in url_patterns
    patterns = getattr(self.urlconf_module, "urlpatterns", self.urlconf_module)
  File "/home/almalinux/.local/lib/python3.9/site-packages/django/utils/functional.py", line 57, in __get__
    res = instance.__dict__[self.name] = self.func(instance)
  File "/home/almalinux/.local/lib/python3.9/site-packages/django/urls/resolvers.py", line 708, in urlconf_module
    return import_module(self.urlconf_name)
  File "/usr/lib64/python3.9/importlib/__init__.py", line 127, in import_module
    return _bootstrap._gcd_import(name[level:], package, level)
  File "<frozen importlib._bootstrap>", line 1030, in _gcd_import
  File "<frozen importlib._bootstrap>", line 1007, in _find_and_load
  File "<frozen importlib._bootstrap>", line 986, in _find_and_load_unlocked
  File "<frozen importlib._bootstrap>", line 680, in _load_unlocked
  File "<frozen importlib._bootstrap_external>", line 850, in exec_module
  File "<frozen importlib._bootstrap>", line 228, in _call_with_frames_removed
  File "/srv/casaaustin/api-casa-austin/src/config/urls.py", line 23, in <module>
    path("api/v1/", include("apps.property.urls")),
  File "/home/almalinux/.local/lib/python3.9/site-packages/django/urls/conf.py", line 38, in include
    urlconf_module = import_module(urlconf_module)
  File "/usr/lib64/python3.9/importlib/__init__.py", line 127, in import_module
    return _bootstrap._gcd_import(name[level:], package, level)
  File "<frozen importlib._bootstrap>", line 1030, in _gcd_import
  File "<frozen importlib._bootstrap>", line 1007, in _find_and_load
  File "<frozen importlib._bootstrap>", line 986, in _find_and_load_unlocked
  File "<frozen importlib._bootstrap>", line 680, in _load_unlocked
  File "<frozen importlib._bootstrap_external>", line 850, in exec_module
  File "<frozen importlib._bootstrap>", line 228, in _call_with_frames_removed
  File "/srv/casaaustin/api-casa-austin/src/apps/property/urls.py", line 1, in <module>
    from .views import (
  File "/srv/casaaustin/api-casa-austin/src/apps/property/views.py", line 3, in <module>
    from django import models
ImportError: cannot import name 'models' from 'django' (/home/almalinux/.local/lib/python3.9/site-packages/django/__init__.py)

During handling of the above exception, another exception occurred:

Traceback (most recent call last):
  File "/home/almalinux/.local/lib/python3.9/site-packages/django/core/handlers/exception.py", line 55, in inner
    response = get_response(request)
  File "/home/almalinux/.local/lib/python3.9/site-packages/django/utils/deprecation.py", line 134, in __call__
    response = response or self.get_response(request)
  File "/home/almalinux/.local/lib/python3.9/site-packages/django/core/handlers/exception.py", line 57, in inner
    response = response_for_exception(request, exc)
  File "/home/almalinux/.local/lib/python3.9/site-packages/django/core/handlers/exception.py", line 140, in response_for_exception
    response = handle_uncaught_exception(
  File "/home/almalinux/.local/lib/python3.9/site-packages/django/core/handlers/exception.py", line 181, in handle_uncaught_exception
    return debug.technical_500_response(request, *exc_info)
  File "/home/almalinux/.local/lib/python3.9/site-packages/django/views/debug.py", line 67, in technical_500_response
    html = reporter.get_traceback_html()
  File "/home/almalinux/.local/lib/python3.9/site-packages/django/views/debug.py", line 410, in get_traceback_html
    c = Context(self.get_traceback_data(), use_l10n=False)
  File "/home/almalinux/.local/lib/python3.9/site-packages/django/views/debug.py", line 393, in get_traceback_data
    c["raising_view_name"] = get_caller(self.request)
  File "/home/almalinux/.local/lib/python3.9/site-packages/django/views/debug.py", line 100, in get_caller
    resolver_match = resolve(request.path)
  File "/home/almalinux/.local/lib/python3.9/site-packages/django/urls/base.py", line 24, in resolve
    return get_resolver(urlconf).resolve(path)
  File "/home/almalinux/.local/lib/python3.9/site-packages/django/urls/resolvers.py", line 663, in resolve
    for pattern in self.url_patterns:
  File "/home/almalinux/.local/lib/python3.9/site-packages/django/utils/functional.py", line 57, in __get__
    res = instance.__dict__[self.name] = self.func(instance)
  File "/home/almalinux/.local/lib/python3.9/site-packages/django/urls/resolvers.py", line 715, in url_patterns
    patterns = getattr(self.urlconf_module, "urlpatterns", self.urlconf_module)
  File "/home/almalinux/.local/lib/python3.9/site-packages/django/utils/functional.py", line 57, in __get__
    res = instance.__dict__[self.name] = self.func(instance)
  File "/home/almalinux/.local/lib/python3.9/site-packages/django/urls/resolvers.py", line 708, in urlconf_module
    return import_module(self.urlconf_name)
  File "/usr/lib64/python3.9/importlib/__init__.py", line 127, in import_module
    return _bootstrap._gcd_import(name[level:], package, level)
  File "<frozen importlib._bootstrap>", line 1030, in _gcd_import
  File "<frozen importlib._bootstrap>", line 1007, in _find_and_load
  File "<frozen importlib._bootstrap>", line 986, in _find_and_load_unlocked
  File "<frozen importlib._bootstrap>", line 680, in _load_unlocked
  File "<frozen importlib._bootstrap_external>", line 850, in exec_module
  File "<frozen importlib._bootstrap>", line 228, in _call_with_frames_removed
  File "/srv/casaaustin/api-casa-austin/src/config/urls.py", line 23, in <module>
    path("api/v1/", include("apps.property.urls")),
  File "/home/almalinux/.local/lib/python3.9/site-packages/django/urls/conf.py", line 38, in include
    urlconf_module = import_module(urlconf_module)
  File "/usr/lib64/python3.9/importlib/__init__.py", line 127, in import_module
    return _bootstrap._gcd_import(name[level:], package, level)
  File "<frozen importlib._bootstrap>", line 1030, in _gcd_import
  File "<frozen importlib._bootstrap>", line 1007, in _find_and_load
  File "<frozen importlib._bootstrap>", line 986, in _find_and_load_unlocked
  File "<frozen importlib._bootstrap>", line 680, in _load_unlocked
  File "<frozen importlib._bootstrap_external>", line 850, in exec_module
  File "<frozen importlib._bootstrap>", line 228, in _call_with_frames_removed
  File "/srv/casaaustin/api-casa-austin/src/apps/property/urls.py", line 1, in <module>
    from .views import (
  File "/srv/casaaustin/api-casa-austin/src/apps/property/views.py", line 3, in <module>
    from django import models
ImportError: cannot import name 'models' from 'django' (/home/almalinux/.local/lib/python3.9/site-packages/django/__init__.py)

During handling of the above exception, another exception occurred:

Traceback (most recent call last):
  File "/home/almalinux/.local/lib/python3.9/site-packages/django/core/handlers/exception.py", line 55, in inner
    response = get_response(request)
  File "/home/almalinux/.local/lib/python3.9/site-packages/django/utils/deprecation.py", line 134, in __call__
    response = response or self.get_response(request)
  File "/home/almalinux/.local/lib/python3.9/site-packages/django/core/handlers/exception.py", line 57, in inner
    response = response_for_exception(request, exc)
  File "/home/almalinux/.local/lib/python3.9/site-packages/django/core/handlers/exception.py", line 140, in response_for_exception
    response = handle_uncaught_exception(
  File "/home/almalinux/.local/lib/python3.9/site-packages/django/core/handlers/exception.py", line 181, in handle_uncaught_exception
    return debug.technical_500_response(request, *exc_info)
  File "/home/almalinux/.local/lib/python3.9/site-packages/django/views/debug.py", line 67, in technical_500_response
    html = reporter.get_traceback_html()
  File "/home/almalinux/.local/lib/python3.9/site-packages/django/views/debug.py", line 410, in get_traceback_html
    c = Context(self.get_traceback_data(), use_l10n=False)
  File "/home/almalinux/.local/lib/python3.9/site-packages/django/views/debug.py", line 393, in get_traceback_data
    c["raising_view_name"] = get_caller(self.request)
  File "/home/almalinux/.local/lib/python3.9/site-packages/django/views/debug.py", line 100, in get_caller
    resolver_match = resolve(request.path)
  File "/home/almalinux/.local/lib/python3.9/site-packages/django/urls/base.py", line 24, in resolve
    return get_resolver(urlconf).resolve(path)
  File "/home/almalinux/.local/lib/python3.9/site-packages/django/urls/resolvers.py", line 663, in resolve
    for pattern in self.url_patterns:
  File "/home/almalinux/.local/lib/python3.9/site-packages/django/utils/functional.py", line 57, in __get__
    res = instance.__dict__[self.name] = self.func(instance)
  File "/home/almalinux/.local/lib/python3.9/site-packages/django/urls/resolvers.py", line 715, in url_patterns
    patterns = getattr(self.urlconf_module, "urlpatterns", self.urlconf_module)
  File "/home/almalinux/.local/lib/python3.9/site-packages/django/utils/functional.py", line 57, in __get__
    res = instance.__dict__[self.name] = self.func(instance)
  File "/home/almalinux/.local/lib/python3.9/site-packages/django/urls/resolvers.py", line 708, in urlconf_module
    return import_module(self.urlconf_name)
  File "/usr/lib64/python3.9/importlib/__init__.py", line 127, in import_module
    return _bootstrap._gcd_import(name[level:], package, level)
  File "<frozen importlib._bootstrap>", line 1030, in _gcd_import
  File "<frozen importlib._bootstrap>", line 1007, in _find_and_load
  File "<frozen importlib._bootstrap>", line 986, in _find_and_load_unlocked
  File "<frozen importlib._bootstrap>", line 680, in _load_unlocked
  File "<frozen importlib._bootstrap_external>", line 850, in exec_module
  File "<frozen importlib._bootstrap>", line 228, in _call_with_frames_removed
  File "/srv/casaaustin/api-casa-austin/src/config/urls.py", line 23, in <module>
    path("api/v1/", include("apps.property.urls")),
  File "/home/almalinux/.local/lib/python3.9/site-packages/django/urls/conf.py", line 38, in include
    urlconf_module = import_module(urlconf_module)
  File "/usr/lib64/python3.9/importlib/__init__.py", line 127, in import_module
    return _bootstrap._gcd_import(name[level:], package, level)
  File "<frozen importlib._bootstrap>", line 1030, in _gcd_import
  File "<frozen importlib._bootstrap>", line 1007, in _find_and_load
  File "<frozen importlib._bootstrap>", line 986, in _find_and_load_unlocked
  File "<frozen importlib._bootstrap>", line 680, in _load_unlocked
  File "<frozen importlib._bootstrap_external>", line 850, in exec_module
  File "<frozen importlib._bootstrap>", line 228, in _call_with_frames_removed
  File "/srv/casaaustin/api-casa-austin/src/apps/property/urls.py", line 1, in <module>
    from .views import (
  File "/srv/casaaustin/api-casa-austin/src/apps/property/views.py", line 3, in <module>
    from django import models
ImportError: cannot import name 'models' from 'django' (/home/almalinux/.local/lib/python3.9/site-packages/django/__init__.py)

During handling of the above exception, another exception occurred:

Traceback (most recent call last):
  File "/home/almalinux/.local/lib/python3.9/site-packages/django/core/handlers/exception.py", line 55, in inner
    response = get_response(request)
  File "/home/almalinux/.local/lib/python3.9/site-packages/django/utils/deprecation.py", line 134, in __call__
    response = response or self.get_response(request)
  File "/home/almalinux/.local/lib/python3.9/site-packages/django/core/handlers/exception.py", line 57, in inner
    response = response_for_exception(request, exc)
  File "/home/almalinux/.local/lib/python3.9/site-packages/django/core/handlers/exception.py", line 140, in response_for_exception
    response = handle_uncaught_exception(
  File "/home/almalinux/.local/lib/python3.9/site-packages/django/core/handlers/exception.py", line 181, in handle_uncaught_exception
    return debug.technical_500_response(request, *exc_info)
  File "/home/almalinux/.local/lib/python3.9/site-packages/django/views/debug.py", line 67, in technical_500_response
    html = reporter.get_traceback_html()
  File "/home/almalinux/.local/lib/python3.9/site-packages/django/views/debug.py", line 410, in get_traceback_html
    c = Context(self.get_traceback_data(), use_l10n=False)
  File "/home/almalinux/.local/lib/python3.9/site-packages/django/views/debug.py", line 393, in get_traceback_data
    c["raising_view_name"] = get_caller(self.request)
  File "/home/almalinux/.local/lib/python3.9/site-packages/django/views/debug.py", line 100, in get_caller
    resolver_match = resolve(request.path)
  File "/home/almalinux/.local/lib/python3.9/site-packages/django/urls/base.py", line 24, in resolve
    return get_resolver(urlconf).resolve(path)
  File "/home/almalinux/.local/lib/python3.9/site-packages/django/urls/resolvers.py", line 663, in resolve
    for pattern in self.url_patterns:
  File "/home/almalinux/.local/lib/python3.9/site-packages/django/utils/functional.py", line 57, in __get__
    res = instance.__dict__[self.name] = self.func(instance)
  File "/home/almalinux/.local/lib/python3.9/site-packages/django/urls/resolvers.py", line 715, in url_patterns
    patterns = getattr(self.urlconf_module, "urlpatterns", self.urlconf_module)
  File "/home/almalinux/.local/lib/python3.9/site-packages/django/utils/functional.py", line 57, in __get__
    res = instance.__dict__[self.name] = self.func(instance)
  File "/home/almalinux/.local/lib/python3.9/site-packages/django/urls/resolvers.py", line 708, in urlconf_module
    return import_module(self.urlconf_name)
  File "/usr/lib64/python3.9/importlib/__init__.py", line 127, in import_module
    return _bootstrap._gcd_import(name[level:], package, level)
  File "<frozen importlib._bootstrap>", line 1030, in _gcd_import
  File "<frozen importlib._bootstrap>", line 1007, in _find_and_load
  File "<frozen importlib._bootstrap>", line 986, in _find_and_load_unlocked
  File "<frozen importlib._bootstrap>", line 680, in _load_unlocked
  File "<frozen importlib._bootstrap_external>", line 850, in exec_module
  File "<frozen importlib._bootstrap>", line 228, in _call_with_frames_removed
  File "/srv/casaaustin/api-casa-austin/src/config/urls.py", line 23, in <module>
    path("api/v1/", include("apps.property.urls")),
  File "/home/almalinux/.local/lib/python3.9/site-packages/django/urls/conf.py", line 38, in include
    urlconf_module = import_module(urlconf_module)
  File "/usr/lib64/python3.9/importlib/__init__.py", line 127, in import_module
    return _bootstrap._gcd_import(name[level:], package, level)
  File "<frozen importlib._bootstrap>", line 1030, in _gcd_import
  File "<frozen importlib._bootstrap>", line 1007, in _find_and_load
  File "<frozen importlib._bootstrap>", line 986, in _find_and_load_unlocked
  File "<frozen importlib._bootstrap>", line 680, in _load_unlocked
  File "<frozen importlib._bootstrap_external>", line 850, in exec_module
  File "<frozen importlib._bootstrap>", line 228, in _call_with_frames_removed
  File "/srv/casaaustin/api-casa-austin/src/apps/property/urls.py", line 1, in <module>
    from .views import (
  File "/srv/casaaustin/api-casa-austin/src/apps/property/views.py", line 3, in <module>
    from django import models
ImportError: cannot import name 'models' from 'django' (/home/almalinux/.local/lib/python3.9/site-packages/django/__init__.py)

During handling of the above exception, another exception occurred:

Traceback (most recent call last):
  File "/home/almalinux/.local/lib/python3.9/site-packages/django/core/handlers/exception.py", line 55, in inner
    response = get_response(request)
  File "/home/almalinux/.local/lib/python3.9/site-packages/django/utils/deprecation.py", line 134, in __call__
    response = response or self.get_response(request)
  File "/home/almalinux/.local/lib/python3.9/site-packages/django/core/handlers/exception.py", line 57, in inner
    response = response_for_exception(request, exc)
  File "/home/almalinux/.local/lib/python3.9/site-packages/django/core/handlers/exception.py", line 140, in response_for_exception
    response = handle_uncaught_exception(
  File "/home/almalinux/.local/lib/python3.9/site-packages/django/core/handlers/exception.py", line 181, in handle_uncaught_exception
    return debug.technical_500_response(request, *exc_info)
  File "/home/almalinux/.local/lib/python3.9/site-packages/django/views/debug.py", line 67, in technical_500_response
    html = reporter.get_traceback_html()
  File "/home/almalinux/.local/lib/python3.9/site-packages/django/views/debug.py", line 410, in get_traceback_html
    c = Context(self.get_traceback_data(), use_l10n=False)
  File "/home/almalinux/.local/lib/python3.9/site-packages/django/views/debug.py", line 393, in get_traceback_data
    c["raising_view_name"] = get_caller(self.request)
  File "/home/almalinux/.local/lib/python3.9/site-packages/django/views/debug.py", line 100, in get_caller
    resolver_match = resolve(request.path)
  File "/home/almalinux/.local/lib/python3.9/site-packages/django/urls/base.py", line 24, in resolve
    return get_resolver(urlconf).resolve(path)
  File "/home/almalinux/.local/lib/python3.9/site-packages/django/urls/resolvers.py", line 663, in resolve
    for pattern in self.url_patterns:
  File "/home/almalinux/.local/lib/python3.9/site-packages/django/utils/functional.py", line 57, in __get__
    res = instance.__dict__[self.name] = self.func(instance)
  File "/home/almalinux/.local/lib/python3.9/site-packages/django/urls/resolvers.py", line 715, in url_patterns
    patterns = getattr(self.urlconf_module, "urlpatterns", self.urlconf_module)
  File "/home/almalinux/.local/lib/python3.9/site-packages/django/utils/functional.py", line 57, in __get__
    res = instance.__dict__[self.name] = self.func(instance)
  File "/home/almalinux/.local/lib/python3.9/site-packages/django/urls/resolvers.py", line 708, in urlconf_module
    return import_module(self.urlconf_name)
  File "/usr/lib64/python3.9/importlib/__init__.py", line 127, in import_module
    return _bootstrap._gcd_import(name[level:], package, level)
  File "<frozen importlib._bootstrap>", line 1030, in _gcd_import
  File "<frozen importlib._bootstrap>", line 1007, in _find_and_load
  File "<frozen importlib._bootstrap>", line 986, in _find_and_load_unlocked
  File "<frozen importlib._bootstrap>", line 680, in _load_unlocked
  File "<frozen importlib._bootstrap_external>", line 850, in exec_module
  File "<frozen importlib._bootstrap>", line 228, in _call_with_frames_removed
  File "/srv/casaaustin/api-casa-austin/src/config/urls.py", line 23, in <module>
    path("api/v1/", include("apps.property.urls")),
  File "/home/almalinux/.local/lib/python3.9/site-packages/django/urls/conf.py", line 38, in include
    urlconf_module = import_module(urlconf_module)
  File "/usr/lib64/python3.9/importlib/__init__.py", line 127, in import_module
    return _bootstrap._gcd_import(name[level:], package, level)
  File "<frozen importlib._bootstrap>", line 1030, in _gcd_import
  File "<frozen importlib._bootstrap>", line 1007, in _find_and_load
  File "<frozen importlib._bootstrap>", line 986, in _find_and_load_unlocked
  File "<frozen importlib._bootstrap>", line 680, in _load_unlocked
  File "<frozen importlib._bootstrap_external>", line 850, in exec_module
  File "<frozen importlib._bootstrap>", line 228, in _call_with_frames_removed
  File "/srv/casaaustin/api-casa-austin/src/apps/property/urls.py", line 1, in <module>
    from .views import (
  File "/srv/casaaustin/api-casa-austin/src/apps/property/views.py", line 3, in <module>
    from django import models
ImportError: cannot import name 'models' from 'django' (/home/almalinux/.local/lib/python3.9/site-packages/django/__init__.py)

During handling of the above exception, another exception occurred:

Traceback (most recent call last):
  File "/home/almalinux/.local/lib/python3.9/site-packages/django/core/handlers/exception.py", line 55, in inner
    response = get_response(request)
  File "/home/almalinux/.local/lib/python3.9/site-packages/django/utils/deprecation.py", line 134, in __call__
    response = response or self.get_response(request)
  File "/home/almalinux/.local/lib/python3.9/site-packages/django/core/handlers/exception.py", line 57, in inner
    response = response_for_exception(request, exc)
  File "/home/almalinux/.local/lib/python3.9/site-packages/django/core/handlers/exception.py", line 140, in response_for_exception
    response = handle_uncaught_exception(
  File "/home/almalinux/.local/lib/python3.9/site-packages/django/core/handlers/exception.py", line 181, in handle_uncaught_exception
    return debug.technical_500_response(request, *exc_info)
  File "/home/almalinux/.local/lib/python3.9/site-packages/django/views/debug.py", line 67, in technical_500_response
    html = reporter.get_traceback_html()
  File "/home/almalinux/.local/lib/python3.9/site-packages/django/views/debug.py", line 410, in get_traceback_html
    c = Context(self.get_traceback_data(), use_l10n=False)
  File "/home/almalinux/.local/lib/python3.9/site-packages/django/views/debug.py", line 393, in get_traceback_data
    c["raising_view_name"] = get_caller(self.request)
  File "/home/almalinux/.local/lib/python3.9/site-packages/django/views/debug.py", line 100, in get_caller
    resolver_match = resolve(request.path)
  File "/home/almalinux/.local/lib/python3.9/site-packages/django/urls/base.py", line 24, in resolve
    return get_resolver(urlconf).resolve(path)
  File "/home/almalinux/.local/lib/python3.9/site-packages/django/urls/resolvers.py", line 663, in resolve
    for pattern in self.url_patterns:
  File "/home/almalinux/.local/lib/python3.9/site-packages/django/utils/functional.py", line 57, in __get__
    res = instance.__dict__[self.name] = self.func(instance)
  File "/home/almalinux/.local/lib/python3.9/site-packages/django/urls/resolvers.py", line 715, in url_patterns
    patterns = getattr(self.urlconf_module, "urlpatterns", self.urlconf_module)
  File "/home/almalinux/.local/lib/python3.9/site-packages/django/utils/functional.py", line 57, in __get__
    res = instance.__dict__[self.name] = self.func(instance)
  File "/home/almalinux/.local/lib/python3.9/site-packages/django/urls/resolvers.py", line 708, in urlconf_module
    return import_module(self.urlconf_name)
  File "/usr/lib64/python3.9/importlib/__init__.py", line 127, in import_module
    return _bootstrap._gcd_import(name[level:], package, level)
  File "<frozen importlib._bootstrap>", line 1030, in _gcd_import
  File "<frozen importlib._bootstrap>", line 1007, in _find_and_load
  File "<frozen importlib._bootstrap>", line 986, in _find_and_load_unlocked
  File "<frozen importlib._bootstrap>", line 680, in _load_unlocked
  File "<frozen importlib._bootstrap_external>", line 850, in exec_module
  File "<frozen importlib._bootstrap>", line 228, in _call_with_frames_removed
  File "/srv/casaaustin/api-casa-austin/src/config/urls.py", line 23, in <module>
    path("api/v1/", include("apps.property.urls")),
  File "/home/almalinux/.local/lib/python3.9/site-packages/django/urls/conf.py", line 38, in include
    urlconf_module = import_module(urlconf_module)
  File "/usr/lib64/python3.9/importlib/__init__.py", line 127, in import_module
    return _bootstrap._gcd_import(name[level:], package, level)
  File "<frozen importlib._bootstrap>", line 1030, in _gcd_import
  File "<frozen importlib._bootstrap>", line 1007, in _find_and_load
  File "<frozen importlib._bootstrap>", line 986, in _find_and_load_unlocked
  File "<frozen importlib._bootstrap>", line 680, in _load_unlocked
  File "<frozen importlib._bootstrap_external>", line 850, in exec_module
  File "<frozen importlib._bootstrap>", line 228, in _call_with_frames_removed
  File "/srv/casaaustin/api-casa-austin/src/apps/property/urls.py", line 1, in <module>
    from .views import (
  File "/srv/casaaustin/api-casa-austin/src/apps/property/views.py", line 3, in <module>
    from django import models
ImportError: cannot import name 'models' from 'django' (/home/almalinux/.local/lib/python3.9/site-packages/django/__init__.py)

During handling of the above exception, another exception occurred:

Traceback (most recent call last):
  File "/home/almalinux/.local/lib/python3.9/site-packages/django/core/handlers/exception.py", line 55, in inner
    response = get_response(request)
  File "/home/almalinux/.local/lib/python3.9/site-packages/django/utils/deprecation.py", line 134, in __call__
    response = response or self.get_response(request)
  File "/home/almalinux/.local/lib/python3.9/site-packages/django/core/handlers/exception.py", line 57, in inner
    response = response_for_exception(request, exc)
  File "/home/almalinux/.local/lib/python3.9/site-packages/django/core/handlers/exception.py", line 140, in response_for_exception
    response = handle_uncaught_exception(
  File "/home/almalinux/.local/lib/python3.9/site-packages/django/core/handlers/exception.py", line 181, in handle_uncaught_exception
    return debug.technical_500_response(request, *exc_info)
  File "/home/almalinux/.local/lib/python3.9/site-packages/django/views/debug.py", line 67, in technical_500_response
    html = reporter.get_traceback_html()
  File "/home/almalinux/.local/lib/python3.9/site-packages/django/views/debug.py", line 410, in get_traceback_html
    c = Context(self.get_traceback_data(), use_l10n=False)
  File "/home/almalinux/.local/lib/python3.9/site-packages/django/views/debug.py", line 393, in get_traceback_data
    c["raising_view_name"] = get_caller(self.request)
  File "/home/almalinux/.local/lib/python3.9/site-packages/django/views/debug.py", line 100, in get_caller
    resolver_match = resolve(request.path)
  File "/home/almalinux/.local/lib/python3.9/site-packages/django/urls/base.py", line 24, in resolve
    return get_resolver(urlconf).resolve(path)
  File "/home/almalinux/.local/lib/python3.9/site-packages/django/urls/resolvers.py", line 663, in resolve
    for pattern in self.url_patterns:
  File "/home/almalinux/.local/lib/python3.9/site-packages/django/utils/functional.py", line 57, in __get__
    res = instance.__dict__[self.name] = self.func(instance)
  File "/home/almalinux/.local/lib/python3.9/site-packages/django/urls/resolvers.py", line 715, in url_patterns
    patterns = getattr(self.urlconf_module, "urlpatterns", self.urlconf_module)
  File "/home/almalinux/.local/lib/python3.9/site-packages/django/utils/functional.py", line 57, in __get__
    res = instance.__dict__[self.name] = self.func(instance)
  File "/home/almalinux/.local/lib/python3.9/site-packages/django/urls/resolvers.py", line 708, in urlconf_module
    return import_module(self.urlconf_name)
  File "/usr/lib64/python3.9/importlib/__init__.py", line 127, in import_module
    return _bootstrap._gcd_import(name[level:], package, level)
  File "<frozen importlib._bootstrap>", line 1030, in _gcd_import
  File "<frozen importlib._bootstrap>", line 1007, in _find_and_load
  File "<frozen importlib._bootstrap>", line 986, in _find_and_load_unlocked
  File "<frozen importlib._bootstrap>", line 680, in _load_unlocked
  File "<frozen importlib._bootstrap_external>", line 850, in exec_module
  File "<frozen importlib._bootstrap>", line 228, in _call_with_frames_removed
  File "/srv/casaaustin/api-casa-austin/src/config/urls.py", line 23, in <module>
    path("api/v1/", include("apps.property.urls")),
  File "/home/almalinux/.local/lib/python3.9/site-packages/django/urls/conf.py", line 38, in include
    urlconf_module = import_module(urlconf_module)
  File "/usr/lib64/python3.9/importlib/__init__.py", line 127, in import_module
    return _bootstrap._gcd_import(name[level:], package, level)
  File "<frozen importlib._bootstrap>", line 1030, in _gcd_import
  File "<frozen importlib._bootstrap>", line 1007, in _find_and_load
  File "<frozen importlib._bootstrap>", line 986, in _find_and_load_unlocked
  File "<frozen importlib._bootstrap>", line 680, in _load_unlocked
  File "<frozen importlib._bootstrap_external>", line 850, in exec_module
  File "<frozen importlib._bootstrap>", line 228, in _call_with_frames_removed
  File "/srv/casaaustin/api-casa-austin/src/apps/property/urls.py", line 1, in <module>
    from .views import (
  File "/srv/casaaustin/api-casa-austin/src/apps/property/views.py", line 3, in <module>
    from django import models
ImportError: cannot import name 'models' from 'django' (/home/almalinux/.local/lib/python3.9/site-packages/django/__init__.py)

During handling of the above exception, another exception occurred:

Traceback (most recent call last):
  File "/home/almalinux/.local/lib/python3.9/site-packages/django/core/handlers/exception.py", line 55, in inner
    response = get_response(request)
  File "/home/almalinux/.local/lib/python3.9/site-packages/corsheaders/middleware.py", line 56, in __call__
    result = self.get_response(request)
  File "/home/almalinux/.local/lib/python3.9/site-packages/django/core/handlers/exception.py", line 57, in inner
    response = response_for_exception(request, exc)
  File "/home/almalinux/.local/lib/python3.9/site-packages/django/core/handlers/exception.py", line 140, in response_for_exception
    response = handle_uncaught_exception(
  File "/home/almalinux/.local/lib/python3.9/site-packages/django/core/handlers/exception.py", line 181, in handle_uncaught_exception
    return debug.technical_500_response(request, *exc_info)
  File "/home/almalinux/.local/lib/python3.9/site-packages/django/views/debug.py", line 67, in technical_500_response
    html = reporter.get_traceback_html()
  File "/home/almalinux/.local/lib/python3.9/site-packages/django/views/debug.py", line 410, in get_traceback_html
    c = Context(self.get_traceback_data(), use_l10n=False)
  File "/home/almalinux/.local/lib/python3.9/site-packages/django/views/debug.py", line 393, in get_traceback_data
    c["raising_view_name"] = get_caller(self.request)
  File "/home/almalinux/.local/lib/python3.9/site-packages/django/views/debug.py", line 100, in get_caller
    resolver_match = resolve(request.path)
  File "/home/almalinux/.local/lib/python3.9/site-packages/django/urls/base.py", line 24, in resolve
    return get_resolver(urlconf).resolve(path)
  File "/home/almalinux/.local/lib/python3.9/site-packages/django/urls/resolvers.py", line 663, in resolve
    for pattern in self.url_patterns:
  File "/home/almalinux/.local/lib/python3.9/site-packages/django/utils/functional.py", line 57, in __get__
    res = instance.__dict__[self.name] = self.func(instance)
  File "/home/almalinux/.local/lib/python3.9/site-packages/django/urls/resolvers.py", line 715, in url_patterns
    patterns = getattr(self.urlconf_module, "urlpatterns", self.urlconf_module)
  File "/home/almalinux/.local/lib/python3.9/site-packages/django/utils/functional.py", line 57, in __get__
    res = instance.__dict__[self.name] = self.func(instance)
  File "/home/almalinux/.local/lib/python3.9/site-packages/django/urls/resolvers.py", line 708, in urlconf_module
    return import_module(self.urlconf_name)
  File "/usr/lib64/python3.9/importlib/__init__.py", line 127, in import_module
    return _bootstrap._gcd_import(name[level:], package, level)
  File "<frozen importlib._bootstrap>", line 1030, in _gcd_import
  File "<frozen importlib._bootstrap>", line 1007, in _find_and_load
  File "<frozen importlib._bootstrap>", line 986, in _find_and_load_unlocked
  File "<frozen importlib._bootstrap>", line 680, in _load_unlocked
  File "<frozen importlib._bootstrap_external>", line 850, in exec_module
  File "<frozen importlib._bootstrap>", line 228, in _call_with_frames_removed
  File "/srv/casaaustin/api-casa-austin/src/config/urls.py", line 23, in <module>
    path("api/v1/", include("apps.property.urls")),
  File "/home/almalinux/.local/lib/python3.9/site-packages/django/urls/conf.py", line 38, in include
    urlconf_module = import_module(urlconf_module)
  File "/usr/lib64/python3.9/importlib/__init__.py", line 127, in import_module
    return _bootstrap._gcd_import(name[level:], package, level)
  File "<frozen importlib._bootstrap>", line 1030, in _gcd_import
  File "<frozen importlib._bootstrap>", line 1007, in _find_and_load
  File "<frozen importlib._bootstrap>", line 986, in _find_and_load_unlocked
  File "<frozen importlib._bootstrap>", line 680, in _load_unlocked
  File "<frozen importlib._bootstrap_external>", line 850, in exec_module
  File "<frozen importlib._bootstrap>", line 228, in _call_with_frames_removed
  File "/srv/casaaustin/api-casa-austin/src/apps/property/urls.py", line 1, in <module>
    from .views import (
  File "/srv/casaaustin/api-casa-austin/src/apps/property/views.py", line 3, in <module>
    from django import models
ImportError: cannot import name 'models' from 'django' (/home/almalinux/.local/lib/python3.9/site-packages/django/__init__.py)

During handling of the above exception, another exception occurred:

Traceback (most recent call last):
  File "/home/almalinux/.local/lib/python3.9/site-packages/gunicorn/workers/sync.py", line 135, in handle
    self.handle_request(listener, req, client, addr)
  File "/home/almalinux/.local/lib/python3.9/site-packages/gunicorn/workers/sync.py", line 178, in handle_request
    respiter = self.wsgi(environ, resp.start_response)
  File "/home/almalinux/.local/lib/python3.9/site-packages/django/core/handlers/wsgi.py", line 124, in __call__
    response = self.get_response(request)
  File "/home/almalinux/.local/lib/python3.9/site-packages/django/core/handlers/base.py", line 140, in get_response
    response = self._middleware_chain(request)
  File "/home/almalinux/.local/lib/python3.9/site-packages/django/core/handlers/exception.py", line 57, in inner
    response = response_for_exception(request, exc)
  File "/home/almalinux/.local/lib/python3.9/site-packages/django/core/handlers/exception.py", line 140, in response_for_exception
    response = handle_uncaught_exception(
  File "/home/almalinux/.local/lib/python3.9/site-packages/django/core/handlers/exception.py", line 181, in handle_uncaught_exception
    return debug.technical_500_response(request, *exc_info)
  File "/home/almalinux/.local/lib/python3.9/site-packages/django/views/debug.py", line 67, in technical_500_response
    html = reporter.get_traceback_html()
  File "/home/almalinux/.local/lib/python3.9/site-packages/django/views/debug.py", line 410, in get_traceback_html
    c = Context(self.get_traceback_data(), use_l10n=False)
  File "/home/almalinux/.local/lib/python3.9/site-packages/django/views/debug.py", line 393, in get_traceback_data
    c["raising_view_name"] = get_caller(self.request)
  File "/home/almalinux/.local/lib/python3.9/site-packages/django/views/debug.py", line 100, in get_caller
    resolver_match = resolve(request.path)
  File "/home/almalinux/.local/lib/python3.9/site-packages/django/urls/base.py", line 24, in resolve
    return get_resolver(urlconf).resolve(path)
  File "/home/almalinux/.local/lib/python3.9/site-packages/django/urls/resolvers.py", line 663, in resolve
    for pattern in self.url_patterns:
  File "/home/almalinux/.local/lib/python3.9/site-packages/django/utils/functional.py", line 57, in __get__
    res = instance.__dict__[self.name] = self.func(instance)
  File "/home/almalinux/.local/lib/python3.9/site-packages/django/urls/resolvers.py", line 715, in url_patterns
    patterns = getattr(self.urlconf_module, "urlpatterns", self.urlconf_module)
  File "/home/almalinux/.local/lib/python3.9/site-packages/django/utils/functional.py", line 57, in __get__
    res = instance.__dict__[self.name] = self.func(instance)
  File "/home/almalinux/.local/lib/python3.9/site-packages/django/urls/resolvers.py", line 708, in urlconf_module
    return import_module(self.urlconf_name)
  File "/usr/lib64/python3.9/importlib/__init__.py", line 127, in import_module
    return _bootstrap._gcd_import(name[level:], package, level)
  File "<frozen importlib._bootstrap>", line 1030, in _gcd_import
  File "<frozen importlib._bootstrap>", line 1007, in _find_and_load
  File "<frozen importlib._bootstrap>", line 986, in _find_and_load_unlocked
  File "<frozen importlib._bootstrap>", line 680, in _load_unlocked
  File "<frozen importlib._bootstrap_external>", line 850, in exec_module
  File "<frozen importlib._bootstrap>", line 228, in _call_with_frames_removed
  File "/srv/casaaustin/api-casa-austin/src/config/urls.py", line 23, in <module>
    path("api/v1/", include("apps.property.urls")),
  File "/home/almalinux/.local/lib/python3.9/site-packages/django/urls/conf.py", line 38, in include
    urlconf_module = import_module(urlconf_module)
  File "/usr/lib64/python3.9/importlib/__init__.py", line 127, in import_module
    return _bootstrap._gcd_import(name[level:], package, level)
  File "<frozen importlib._bootstrap>", line 1030, in _gcd_import
  File "<frozen importlib._bootstrap>", line 1007, in _find_and_load
  File "<frozen importlib._bootstrap>", line 986, in _find_and_load_unlocked
  File "<frozen importlib._bootstrap>", line 680, in _load_unlocked
  File "<frozen importlib._bootstrap_external>", line 850, in exec_module
  File "<frozen importlib._bootstrap>", line 228, in _call_with_frames_removed
  File "/srv/casaaustin/api-casa-austin/src/apps/property/urls.py", line 1, in <module>
    from .views import (
  File "/srv/casaaustin/api-casa-austin/src/apps/property/views.py", line 3, in <module>
    from django import models
ImportError: cannot import name 'models' from 'django' (/home/almalinux/.local/lib/python3.9/site-packages/django/__init__.py)
[2025-09-07 16:20:43 -0500] [1428959] [ERROR] Error handling request /favicon.ico
Traceback (most recent call last):
  File "/home/almalinux/.local/lib/python3.9/site-packages/django/core/handlers/exception.py", line 55, in inner
    response = get_response(request)
  File "/home/almalinux/.local/lib/python3.9/site-packages/django/core/handlers/base.py", line 181, in _get_response
    callback, callback_args, callback_kwargs = self.resolve_request(request)
  File "/home/almalinux/.local/lib/python3.9/site-packages/django/core/handlers/base.py", line 313, in resolve_request
    resolver_match = resolver.resolve(request.path_info)
  File "/home/almalinux/.local/lib/python3.9/site-packages/django/urls/resolvers.py", line 663, in resolve
    for pattern in self.url_patterns:
  File "/home/almalinux/.local/lib/python3.9/site-packages/django/utils/functional.py", line 57, in __get__
    res = instance.__dict__[self.name] = self.func(instance)
  File "/home/almalinux/.local/lib/python3.9/site-packages/django/urls/resolvers.py", line 715, in url_patterns
    patterns = getattr(self.urlconf_module, "urlpatterns", self.urlconf_module)
  File "/home/almalinux/.local/lib/python3.9/site-packages/django/utils/functional.py", line 57, in __get__
    res = instance.__dict__[self.name] = self.func(instance)
  File "/home/almalinux/.local/lib/python3.9/site-packages/django/urls/resolvers.py", line 708, in urlconf_module
    return import_module(self.urlconf_name)
  File "/usr/lib64/python3.9/importlib/__init__.py", line 127, in import_module
    return _bootstrap._gcd_import(name[level:], package, level)
  File "<frozen importlib._bootstrap>", line 1030, in _gcd_import
  File "<frozen importlib._bootstrap>", line 1007, in _find_and_load
  File "<frozen importlib._bootstrap>", line 986, in _find_and_load_unlocked
  File "<frozen importlib._bootstrap>", line 680, in _load_unlocked
  File "<frozen importlib._bootstrap_external>", line 850, in exec_module
  File "<frozen importlib._bootstrap>", line 228, in _call_with_frames_removed
  File "/srv/casaaustin/api-casa-austin/src/config/urls.py", line 23, in <module>
    path("api/v1/", include("apps.property.urls")),
  File "/home/almalinux/.local/lib/python3.9/site-packages/django/urls/conf.py", line 38, in include
    urlconf_module = import_module(urlconf_module)
  File "/usr/lib64/python3.9/importlib/__init__.py", line 127, in import_module
    return _bootstrap._gcd_import(name[level:], package, level)
  File "<frozen importlib._bootstrap>", line 1030, in _gcd_import
  File "<frozen importlib._bootstrap>", line 1007, in _find_and_load
  File "<frozen importlib._bootstrap>", line 986, in _find_and_load_unlocked
  File "<frozen importlib._bootstrap>", line 680, in _load_unlocked
  File "<frozen importlib._bootstrap_external>", line 850, in exec_module
  File "<frozen importlib._bootstrap>", line 228, in _call_with_frames_removed
  File "/srv/casaaustin/api-casa-austin/src/apps/property/urls.py", line 1, in <module>
    from .views import (
  File "/srv/casaaustin/api-casa-austin/src/apps/property/views.py", line 3, in <module>
    from django import models
ImportError: cannot import name 'models' from 'django' (/home/almalinux/.local/lib/python3.9/site-packages/django/__init__.py)

During handling of the above exception, another exception occurred:

Traceback (most recent call last):
  File "/home/almalinux/.local/lib/python3.9/site-packages/django/core/handlers/exception.py", line 55, in inner
    response = get_response(request)
  File "/home/almalinux/.local/lib/python3.9/site-packages/django/utils/deprecation.py", line 134, in __call__
    response = response or self.get_response(request)
  File "/home/almalinux/.local/lib/python3.9/site-packages/django/core/handlers/exception.py", line 57, in inner
    response = response_for_exception(request, exc)
  File "/home/almalinux/.local/lib/python3.9/site-packages/django/core/handlers/exception.py", line 140, in response_for_exception
    response = handle_uncaught_exception(
  File "/home/almalinux/.local/lib/python3.9/site-packages/django/core/handlers/exception.py", line 181, in handle_uncaught_exception
    return debug.technical_500_response(request, *exc_info)
  File "/home/almalinux/.local/lib/python3.9/site-packages/django/views/debug.py", line 67, in technical_500_response
    html = reporter.get_traceback_html()
  File "/home/almalinux/.local/lib/python3.9/site-packages/django/views/debug.py", line 410, in get_traceback_html
    c = Context(self.get_traceback_data(), use_l10n=False)
  File "/home/almalinux/.local/lib/python3.9/site-packages/django/views/debug.py", line 393, in get_traceback_data
    c["raising_view_name"] = get_caller(self.request)
  File "/home/almalinux/.local/lib/python3.9/site-packages/django/views/debug.py", line 100, in get_caller
    resolver_match = resolve(request.path)
  File "/home/almalinux/.local/lib/python3.9/site-packages/django/urls/base.py", line 24, in resolve
    return get_resolver(urlconf).resolve(path)
  File "/home/almalinux/.local/lib/python3.9/site-packages/django/urls/resolvers.py", line 663, in resolve
    for pattern in self.url_patterns:
  File "/home/almalinux/.local/lib/python3.9/site-packages/django/utils/functional.py", line 57, in __get__
    res = instance.__dict__[self.name] = self.func(instance)
  File "/home/almalinux/.local/lib/python3.9/site-packages/django/urls/resolvers.py", line 715, in url_patterns
    patterns = getattr(self.urlconf_module, "urlpatterns", self.urlconf_module)
  File "/home/almalinux/.local/lib/python3.9/site-packages/django/utils/functional.py", line 57, in __get__
    res = instance.__dict__[self.name] = self.func(instance)
  File "/home/almalinux/.local/lib/python3.9/site-packages/django/urls/resolvers.py", line 708, in urlconf_module
    return import_module(self.urlconf_name)
  File "/usr/lib64/python3.9/importlib/__init__.py", line 127, in import_module
    return _bootstrap._gcd_import(name[level:], package, level)
  File "<frozen importlib._bootstrap>", line 1030, in _gcd_import
  File "<frozen importlib._bootstrap>", line 1007, in _find_and_load
  File "<frozen importlib._bootstrap>", line 986, in _find_and_load_unlocked
  File "<frozen importlib._bootstrap>", line 680, in _load_unlocked
  File "<frozen importlib._bootstrap_external>", line 850, in exec_module
  File "<frozen importlib._bootstrap>", line 228, in _call_with_frames_removed
  File "/srv/casaaustin/api-casa-austin/src/config/urls.py", line 23, in <module>
    path("api/v1/", include("apps.property.urls")),
  File "/home/almalinux/.local/lib/python3.9/site-packages/django/urls/conf.py", line 38, in include
    urlconf_module = import_module(urlconf_module)
  File "/usr/lib64/python3.9/importlib/__init__.py", line 127, in import_module
    return _bootstrap._gcd_import(name[level:], package, level)
  File "<frozen importlib._bootstrap>", line 1030, in _gcd_import
  File "<frozen importlib._bootstrap>", line 1007, in _find_and_load
  File "<frozen importlib._bootstrap>", line 986, in _find_and_load_unlocked
  File "<frozen importlib._bootstrap>", line 680, in _load_unlocked
  File "<frozen importlib._bootstrap_external>", line 850, in exec_module
  File "<frozen importlib._bootstrap>", line 228, in _call_with_frames_removed
  File "/srv/casaaustin/api-casa-austin/src/apps/property/urls.py", line 1, in <module>
    from .views import (
  File "/srv/casaaustin/api-casa-austin/src/apps/property/views.py", line 3, in <module>
    from django import models
ImportError: cannot import name 'models' from 'django' (/home/almalinux/.local/lib/python3.9/site-packages/django/__init__.py)

During handling of the above exception, another exception occurred:

Traceback (most recent call last):
  File "/home/almalinux/.local/lib/python3.9/site-packages/django/core/handlers/exception.py", line 55, in inner
    response = get_response(request)
  File "/home/almalinux/.local/lib/python3.9/site-packages/django/utils/deprecation.py", line 134, in __call__
    response = response or self.get_response(request)
  File "/home/almalinux/.local/lib/python3.9/site-packages/django/core/handlers/exception.py", line 57, in inner
    response = response_for_exception(request, exc)
  File "/home/almalinux/.local/lib/python3.9/site-packages/django/core/handlers/exception.py", line 140, in response_for_exception
    response = handle_uncaught_exception(
  File "/home/almalinux/.local/lib/python3.9/site-packages/django/core/handlers/exception.py", line 181, in handle_uncaught_exception
    return debug.technical_500_response(request, *exc_info)
  File "/home/almalinux/.local/lib/python3.9/site-packages/django/views/debug.py", line 67, in technical_500_response
    html = reporter.get_traceback_html()
  File "/home/almalinux/.local/lib/python3.9/site-packages/django/views/debug.py", line 410, in get_traceback_html
    c = Context(self.get_traceback_data(), use_l10n=False)
  File "/home/almalinux/.local/lib/python3.9/site-packages/django/views/debug.py", line 393, in get_traceback_data
    c["raising_view_name"] = get_caller(self.request)
  File "/home/almalinux/.local/lib/python3.9/site-packages/django/views/debug.py", line 100, in get_caller
    resolver_match = resolve(request.path)
  File "/home/almalinux/.local/lib/python3.9/site-packages/django/urls/base.py", line 24, in resolve
    return get_resolver(urlconf).resolve(path)
  File "/home/almalinux/.local/lib/python3.9/site-packages/django/urls/resolvers.py", line 663, in resolve
    for pattern in self.url_patterns:
  File "/home/almalinux/.local/lib/python3.9/site-packages/django/utils/functional.py", line 57, in __get__
    res = instance.__dict__[self.name] = self.func(instance)
  File "/home/almalinux/.local/lib/python3.9/site-packages/django/urls/resolvers.py", line 715, in url_patterns
    patterns = getattr(self.urlconf_module, "urlpatterns", self.urlconf_module)
  File "/home/almalinux/.local/lib/python3.9/site-packages/django/utils/functional.py", line 57, in __get__
    res = instance.__dict__[self.name] = self.func(instance)
  File "/home/almalinux/.local/lib/python3.9/site-packages/django/urls/resolvers.py", line 708, in urlconf_module
    return import_module(self.urlconf_name)
  File "/usr/lib64/python3.9/importlib/__init__.py", line 127, in import_module
    return _bootstrap._gcd_import(name[level:], package, level)
  File "<frozen importlib._bootstrap>", line 1030, in _gcd_import
  File "<frozen importlib._bootstrap>", line 1007, in _find_and_load
  File "<frozen importlib._bootstrap>", line 986, in _find_and_load_unlocked
  File "<frozen importlib._bootstrap>", line 680, in _load_unlocked
  File "<frozen importlib._bootstrap_external>", line 850, in exec_module
  File "<frozen importlib._bootstrap>", line 228, in _call_with_frames_removed
  File "/srv/casaaustin/api-casa-austin/src/config/urls.py", line 23, in <module>
    path("api/v1/", include("apps.property.urls")),
  File "/home/almalinux/.local/lib/python3.9/site-packages/django/urls/conf.py", line 38, in include
    urlconf_module = import_module(urlconf_module)
  File "/usr/lib64/python3.9/importlib/__init__.py", line 127, in import_module
    return _bootstrap._gcd_import(name[level:], package, level)
  File "<frozen importlib._bootstrap>", line 1030, in _gcd_import
  File "<frozen importlib._bootstrap>", line 1007, in _find_and_load
  File "<frozen importlib._bootstrap>", line 986, in _find_and_load_unlocked
  File "<frozen importlib._bootstrap>", line 680, in _load_unlocked
  File "<frozen importlib._bootstrap_external>", line 850, in exec_module
  File "<frozen importlib._bootstrap>", line 228, in _call_with_frames_removed
  File "/srv/casaaustin/api-casa-austin/src/apps/property/urls.py", line 1, in <module>
    from .views import (
  File "/srv/casaaustin/api-casa-austin/src/apps/property/views.py", line 3, in <module>
    from django import models
ImportError: cannot import name 'models' from 'django' (/home/almalinux/.local/lib/python3.9/site-packages/django/__init__.py)

During handling of the above exception, another exception occurred:

Traceback (most recent call last):
  File "/home/almalinux/.local/lib/python3.9/site-packages/django/core/handlers/exception.py", line 55, in inner
    response = get_response(request)
  File "/home/almalinux/.local/lib/python3.9/site-packages/django/utils/deprecation.py", line 134, in __call__
    response = response or self.get_response(request)
  File "/home/almalinux/.local/lib/python3.9/site-packages/django/core/handlers/exception.py", line 57, in inner
    response = response_for_exception(request, exc)
  File "/home/almalinux/.local/lib/python3.9/site-packages/django/core/handlers/exception.py", line 140, in response_for_exception
    response = handle_uncaught_exception(
  File "/home/almalinux/.local/lib/python3.9/site-packages/django/core/handlers/exception.py", line 181, in handle_uncaught_exception
    return debug.technical_500_response(request, *exc_info)
  File "/home/almalinux/.local/lib/python3.9/site-packages/django/views/debug.py", line 67, in technical_500_response
    html = reporter.get_traceback_html()
  File "/home/almalinux/.local/lib/python3.9/site-packages/django/views/debug.py", line 410, in get_traceback_html
    c = Context(self.get_traceback_data(), use_l10n=False)
  File "/home/almalinux/.local/lib/python3.9/site-packages/django/views/debug.py", line 393, in get_traceback_data
    c["raising_view_name"] = get_caller(self.request)
  File "/home/almalinux/.local/lib/python3.9/site-packages/django/views/debug.py", line 100, in get_caller
    resolver_match = resolve(request.path)
  File "/home/almalinux/.local/lib/python3.9/site-packages/django/urls/base.py", line 24, in resolve
    return get_resolver(urlconf).resolve(path)
  File "/home/almalinux/.local/lib/python3.9/site-packages/django/urls/resolvers.py", line 663, in resolve
    for pattern in self.url_patterns:
  File "/home/almalinux/.local/lib/python3.9/site-packages/django/utils/functional.py", line 57, in __get__
    res = instance.__dict__[self.name] = self.func(instance)
  File "/home/almalinux/.local/lib/python3.9/site-packages/django/urls/resolvers.py", line 715, in url_patterns
    patterns = getattr(self.urlconf_module, "urlpatterns", self.urlconf_module)
  File "/home/almalinux/.local/lib/python3.9/site-packages/django/utils/functional.py", line 57, in __get__
    res = instance.__dict__[self.name] = self.func(instance)
  File "/home/almalinux/.local/lib/python3.9/site-packages/django/urls/resolvers.py", line 708, in urlconf_module
    return import_module(self.urlconf_name)
  File "/usr/lib64/python3.9/importlib/__init__.py", line 127, in import_module
    return _bootstrap._gcd_import(name[level:], package, level)
  File "<frozen importlib._bootstrap>", line 1030, in _gcd_import
  File "<frozen importlib._bootstrap>", line 1007, in _find_and_load
  File "<frozen importlib._bootstrap>", line 986, in _find_and_load_unlocked
  File "<frozen importlib._bootstrap>", line 680, in _load_unlocked
  File "<frozen importlib._bootstrap_external>", line 850, in exec_module
  File "<frozen importlib._bootstrap>", line 228, in _call_with_frames_removed
  File "/srv/casaaustin/api-casa-austin/src/config/urls.py", line 23, in <module>
    path("api/v1/", include("apps.property.urls")),
  File "/home/almalinux/.local/lib/python3.9/site-packages/django/urls/conf.py", line 38, in include
    urlconf_module = import_module(urlconf_module)
  File "/usr/lib64/python3.9/importlib/__init__.py", line 127, in import_module
    return _bootstrap._gcd_import(name[level:], package, level)
  File "<frozen importlib._bootstrap>", line 1030, in _gcd_import
  File "<frozen importlib._bootstrap>", line 1007, in _find_and_load
  File "<frozen importlib._bootstrap>", line 986, in _find_and_load_unlocked
  File "<frozen importlib._bootstrap>", line 680, in _load_unlocked
  File "<frozen importlib._bootstrap_external>", line 850, in exec_module
  File "<frozen importlib._bootstrap>", line 228, in _call_with_frames_removed
  File "/srv/casaaustin/api-casa-austin/src/apps/property/urls.py", line 1, in <module>
    from .views import (
  File "/srv/casaaustin/api-casa-austin/src/apps/property/views.py", line 3, in <module>
    from django import models
ImportError: cannot import name 'models' from 'django' (/home/almalinux/.local/lib/python3.9/site-packages/django/__init__.py)

During handling of the above exception, another exception occurred:

Traceback (most recent call last):
  File "/home/almalinux/.local/lib/python3.9/site-packages/django/core/handlers/exception.py", line 55, in inner
    response = get_response(request)
  File "/home/almalinux/.local/lib/python3.9/site-packages/django/utils/deprecation.py", line 134, in __call__
    response = response or self.get_response(request)
  File "/home/almalinux/.local/lib/python3.9/site-packages/django/core/handlers/exception.py", line 57, in inner
    response = response_for_exception(request, exc)
  File "/home/almalinux/.local/lib/python3.9/site-packages/django/core/handlers/exception.py", line 140, in response_for_exception
    response = handle_uncaught_exception(
  File "/home/almalinux/.local/lib/python3.9/site-packages/django/core/handlers/exception.py", line 181, in handle_uncaught_exception
    return debug.technical_500_response(request, *exc_info)
  File "/home/almalinux/.local/lib/python3.9/site-packages/django/views/debug.py", line 67, in technical_500_response
    html = reporter.get_traceback_html()
  File "/home/almalinux/.local/lib/python3.9/site-packages/django/views/debug.py", line 410, in get_traceback_html
    c = Context(self.get_traceback_data(), use_l10n=False)
  File "/home/almalinux/.local/lib/python3.9/site-packages/django/views/debug.py", line 393, in get_traceback_data
    c["raising_view_name"] = get_caller(self.request)
  File "/home/almalinux/.local/lib/python3.9/site-packages/django/views/debug.py", line 100, in get_caller
    resolver_match = resolve(request.path)
  File "/home/almalinux/.local/lib/python3.9/site-packages/django/urls/base.py", line 24, in resolve
    return get_resolver(urlconf).resolve(path)
  File "/home/almalinux/.local/lib/python3.9/site-packages/django/urls/resolvers.py", line 663, in resolve
    for pattern in self.url_patterns:
  File "/home/almalinux/.local/lib/python3.9/site-packages/django/utils/functional.py", line 57, in __get__
    res = instance.__dict__[self.name] = self.func(instance)
  File "/home/almalinux/.local/lib/python3.9/site-packages/django/urls/resolvers.py", line 715, in url_patterns
    patterns = getattr(self.urlconf_module, "urlpatterns", self.urlconf_module)
  File "/home/almalinux/.local/lib/python3.9/site-packages/django/utils/functional.py", line 57, in __get__
    res = instance.__dict__[self.name] = self.func(instance)
  File "/home/almalinux/.local/lib/python3.9/site-packages/django/urls/resolvers.py", line 708, in urlconf_module
    return import_module(self.urlconf_name)
  File "/usr/lib64/python3.9/importlib/__init__.py", line 127, in import_module
    return _bootstrap._gcd_import(name[level:], package, level)
  File "<frozen importlib._bootstrap>", line 1030, in _gcd_import
  File "<frozen importlib._bootstrap>", line 1007, in _find_and_load
  File "<frozen importlib._bootstrap>", line 986, in _find_and_load_unlocked
  File "<frozen importlib._bootstrap>", line 680, in _load_unlocked
  File "<frozen importlib._bootstrap_external>", line 850, in exec_module
  File "<frozen importlib._bootstrap>", line 228, in _call_with_frames_removed
  File "/srv/casaaustin/api-casa-austin/src/config/urls.py", line 23, in <module>
    path("api/v1/", include("apps.property.urls")),
  File "/home/almalinux/.local/lib/python3.9/site-packages/django/urls/conf.py", line 38, in include
    urlconf_module = import_module(urlconf_module)
  File "/usr/lib64/python3.9/importlib/__init__.py", line 127, in import_module
    return _bootstrap._gcd_import(name[level:], package, level)
  File "<frozen importlib._bootstrap>", line 1030, in _gcd_import
  File "<frozen importlib._bootstrap>", line 1007, in _find_and_load
  File "<frozen importlib._bootstrap>", line 986, in _find_and_load_unlocked
  File "<frozen importlib._bootstrap>", line 680, in _load_unlocked
  File "<frozen importlib._bootstrap_external>", line 850, in exec_module
  File "<frozen importlib._bootstrap>", line 228, in _call_with_frames_removed
  File "/srv/casaaustin/api-casa-austin/src/apps/property/urls.py", line 1, in <module>
    from .views import (
  File "/srv/casaaustin/api-casa-austin/src/apps/property/views.py", line 3, in <module>
    from django import models
ImportError: cannot import name 'models' from 'django' (/home/almalinux/.local/lib/python3.9/site-packages/django/__init__.py)

During handling of the above exception, another exception occurred:

Traceback (most recent call last):
  File "/home/almalinux/.local/lib/python3.9/site-packages/django/core/handlers/exception.py", line 55, in inner
    response = get_response(request)
  File "/home/almalinux/.local/lib/python3.9/site-packages/django/utils/deprecation.py", line 134, in __call__
    response = response or self.get_response(request)
  File "/home/almalinux/.local/lib/python3.9/site-packages/django/core/handlers/exception.py", line 57, in inner
    response = response_for_exception(request, exc)
  File "/home/almalinux/.local/lib/python3.9/site-packages/django/core/handlers/exception.py", line 140, in response_for_exception
    response = handle_uncaught_exception(
  File "/home/almalinux/.local/lib/python3.9/site-packages/django/core/handlers/exception.py", line 181, in handle_uncaught_exception
    return debug.technical_500_response(request, *exc_info)
  File "/home/almalinux/.local/lib/python3.9/site-packages/django/views/debug.py", line 67, in technical_500_response
    html = reporter.get_traceback_html()
  File "/home/almalinux/.local/lib/python3.9/site-packages/django/views/debug.py", line 410, in get_traceback_html
    c = Context(self.get_traceback_data(), use_l10n=False)
  File "/home/almalinux/.local/lib/python3.9/site-packages/django/views/debug.py", line 393, in get_traceback_data
    c["raising_view_name"] = get_caller(self.request)
  File "/home/almalinux/.local/lib/python3.9/site-packages/django/views/debug.py", line 100, in get_caller
    resolver_match = resolve(request.path)
  File "/home/almalinux/.local/lib/python3.9/site-packages/django/urls/base.py", line 24, in resolve
    return get_resolver(urlconf).resolve(path)
  File "/home/almalinux/.local/lib/python3.9/site-packages/django/urls/resolvers.py", line 663, in resolve
    for pattern in self.url_patterns:
  File "/home/almalinux/.local/lib/python3.9/site-packages/django/utils/functional.py", line 57, in __get__
    res = instance.__dict__[self.name] = self.func(instance)
  File "/home/almalinux/.local/lib/python3.9/site-packages/django/urls/resolvers.py", line 715, in url_patterns
    patterns = getattr(self.urlconf_module, "urlpatterns", self.urlconf_module)
  File "/home/almalinux/.local/lib/python3.9/site-packages/django/utils/functional.py", line 57, in __get__
    res = instance.__dict__[self.name] = self.func(instance)
  File "/home/almalinux/.local/lib/python3.9/site-packages/django/urls/resolvers.py", line 708, in urlconf_module
    return import_module(self.urlconf_name)
  File "/usr/lib64/python3.9/importlib/__init__.py", line 127, in import_module
    return _bootstrap._gcd_import(name[level:], package, level)
  File "<frozen importlib._bootstrap>", line 1030, in _gcd_import
  File "<frozen importlib._bootstrap>", line 1007, in _find_and_load
  File "<frozen importlib._bootstrap>", line 986, in _find_and_load_unlocked
  File "<frozen importlib._bootstrap>", line 680, in _load_unlocked
  File "<frozen importlib._bootstrap_external>", line 850, in exec_module
  File "<frozen importlib._bootstrap>", line 228, in _call_with_frames_removed
  File "/srv/casaaustin/api-casa-austin/src/config/urls.py", line 23, in <module>
    path("api/v1/", include("apps.property.urls")),
  File "/home/almalinux/.local/lib/python3.9/site-packages/django/urls/conf.py", line 38, in include
    urlconf_module = import_module(urlconf_module)
  File "/usr/lib64/python3.9/importlib/__init__.py", line 127, in import_module
    return _bootstrap._gcd_import(name[level:], package, level)
  File "<frozen importlib._bootstrap>", line 1030, in _gcd_import
  File "<frozen importlib._bootstrap>", line 1007, in _find_and_load
  File "<frozen importlib._bootstrap>", line 986, in _find_and_load_unlocked
  File "<frozen importlib._bootstrap>", line 680, in _load_unlocked
  File "<frozen importlib._bootstrap_external>", line 850, in exec_module
  File "<frozen importlib._bootstrap>", line 228, in _call_with_frames_removed
  File "/srv/casaaustin/api-casa-austin/src/apps/property/urls.py", line 1, in <module>
    from .views import (
  File "/srv/casaaustin/api-casa-austin/src/apps/property/views.py", line 3, in <module>
    from django import models
ImportError: cannot import name 'models' from 'django' (/home/almalinux/.local/lib/python3.9/site-packages/django/__init__.py)

During handling of the above exception, another exception occurred:

Traceback (most recent call last):
  File "/home/almalinux/.local/lib/python3.9/site-packages/django/core/handlers/exception.py", line 55, in inner
    response = get_response(request)
  File "/home/almalinux/.local/lib/python3.9/site-packages/django/utils/deprecation.py", line 134, in __call__
    response = response or self.get_response(request)
  File "/home/almalinux/.local/lib/python3.9/site-packages/django/core/handlers/exception.py", line 57, in inner
    response = response_for_exception(request, exc)
  File "/home/almalinux/.local/lib/python3.9/site-packages/django/core/handlers/exception.py", line 140, in response_for_exception
    response = handle_uncaught_exception(
  File "/home/almalinux/.local/lib/python3.9/site-packages/django/core/handlers/exception.py", line 181, in handle_uncaught_exception
    return debug.technical_500_response(request, *exc_info)
  File "/home/almalinux/.local/lib/python3.9/site-packages/django/views/debug.py", line 67, in technical_500_response
    html = reporter.get_traceback_html()
  File "/home/almalinux/.local/lib/python3.9/site-packages/django/views/debug.py", line 410, in get_traceback_html
    c = Context(self.get_traceback_data(), use_l10n=False)
  File "/home/almalinux/.local/lib/python3.9/site-packages/django/views/debug.py", line 393, in get_traceback_data
    c["raising_view_name"] = get_caller(self.request)
  File "/home/almalinux/.local/lib/python3.9/site-packages/django/views/debug.py", line 100, in get_caller
    resolver_match = resolve(request.path)
  File "/home/almalinux/.local/lib/python3.9/site-packages/django/urls/base.py", line 24, in resolve
    return get_resolver(urlconf).resolve(path)
  File "/home/almalinux/.local/lib/python3.9/site-packages/django/urls/resolvers.py", line 663, in resolve
    for pattern in self.url_patterns:
  File "/home/almalinux/.local/lib/python3.9/site-packages/django/utils/functional.py", line 57, in __get__
    res = instance.__dict__[self.name] = self.func(instance)
  File "/home/almalinux/.local/lib/python3.9/site-packages/django/urls/resolvers.py", line 715, in url_patterns
    patterns = getattr(self.urlconf_module, "urlpatterns", self.urlconf_module)
  File "/home/almalinux/.local/lib/python3.9/site-packages/django/utils/functional.py", line 57, in __get__
    res = instance.__dict__[self.name] = self.func(instance)
  File "/home/almalinux/.local/lib/python3.9/site-packages/django/urls/resolvers.py", line 708, in urlconf_module
    return import_module(self.urlconf_name)
  File "/usr/lib64/python3.9/importlib/__init__.py", line 127, in import_module
    return _bootstrap._gcd_import(name[level:], package, level)
  File "<frozen importlib._bootstrap>", line 1030, in _gcd_import
  File "<frozen importlib._bootstrap>", line 1007, in _find_and_load
  File "<frozen importlib._bootstrap>", line 986, in _find_and_load_unlocked
  File "<frozen importlib._bootstrap>", line 680, in _load_unlocked
  File "<frozen importlib._bootstrap_external>", line 850, in exec_module
  File "<frozen importlib._bootstrap>", line 228, in _call_with_frames_removed
  File "/srv/casaaustin/api-casa-austin/src/config/urls.py", line 23, in <module>
    path("api/v1/", include("apps.property.urls")),
  File "/home/almalinux/.local/lib/python3.9/site-packages/django/urls/conf.py", line 38, in include
    urlconf_module = import_module(urlconf_module)
  File "/usr/lib64/python3.9/importlib/__init__.py", line 127, in import_module
    return _bootstrap._gcd_import(name[level:], package, level)
  File "<frozen importlib._bootstrap>", line 1030, in _gcd_import
  File "<frozen importlib._bootstrap>", line 1007, in _find_and_load
  File "<frozen importlib._bootstrap>", line 986, in _find_and_load_unlocked
  File "<frozen importlib._bootstrap>", line 680, in _load_unlocked
  File "<frozen importlib._bootstrap_external>", line 850, in exec_module
  File "<frozen importlib._bootstrap>", line 228, in _call_with_frames_removed
  File "/srv/casaaustin/api-casa-austin/src/apps/property/urls.py", line 1, in <module>
    from .views import (
  File "/srv/casaaustin/api-casa-austin/src/apps/property/views.py", line 3, in <module>
    from django import models
ImportError: cannot import name 'models' from 'django' (/home/almalinux/.local/lib/python3.9/site-packages/django/__init__.py)

During handling of the above exception, another exception occurred:

Traceback (most recent call last):
  File "/home/almalinux/.local/lib/python3.9/site-packages/django/core/handlers/exception.py", line 55, in inner
    response = get_response(request)
  File "/home/almalinux/.local/lib/python3.9/site-packages/django/utils/deprecation.py", line 134, in __call__
    response = response or self.get_response(request)
  File "/home/almalinux/.local/lib/python3.9/site-packages/django/core/handlers/exception.py", line 57, in inner
    response = response_for_exception(request, exc)
  File "/home/almalinux/.local/lib/python3.9/site-packages/django/core/handlers/exception.py", line 140, in response_for_exception
    response = handle_uncaught_exception(
  File "/home/almalinux/.local/lib/python3.9/site-packages/django/core/handlers/exception.py", line 181, in handle_uncaught_exception
    return debug.technical_500_response(request, *exc_info)
  File "/home/almalinux/.local/lib/python3.9/site-packages/django/views/debug.py", line 67, in technical_500_response
    html = reporter.get_traceback_html()
  File "/home/almalinux/.local/lib/python3.9/site-packages/django/views/debug.py", line 410, in get_traceback_html
    c = Context(self.get_traceback_data(), use_l10n=False)
  File "/home/almalinux/.local/lib/python3.9/site-packages/django/views/debug.py", line 393, in get_traceback_data
    c["raising_view_name"] = get_caller(self.request)
  File "/home/almalinux/.local/lib/python3.9/site-packages/django/views/debug.py", line 100, in get_caller
    resolver_match = resolve(request.path)
  File "/home/almalinux/.local/lib/python3.9/site-packages/django/urls/base.py", line 24, in resolve
    return get_resolver(urlconf).resolve(path)
  File "/home/almalinux/.local/lib/python3.9/site-packages/django/urls/resolvers.py", line 663, in resolve
    for pattern in self.url_patterns:
  File "/home/almalinux/.local/lib/python3.9/site-packages/django/utils/functional.py", line 57, in __get__
    res = instance.__dict__[self.name] = self.func(instance)
  File "/home/almalinux/.local/lib/python3.9/site-packages/django/urls/resolvers.py", line 715, in url_patterns
    patterns = getattr(self.urlconf_module, "urlpatterns", self.urlconf_module)
  File "/home/almalinux/.local/lib/python3.9/site-packages/django/utils/functional.py", line 57, in __get__
    res = instance.__dict__[self.name] = self.func(instance)
  File "/home/almalinux/.local/lib/python3.9/site-packages/django/urls/resolvers.py", line 708, in urlconf_module
    return import_module(self.urlconf_name)
  File "/usr/lib64/python3.9/importlib/__init__.py", line 127, in import_module
    return _bootstrap._gcd_import(name[level:], package, level)
  File "<frozen importlib._bootstrap>", line 1030, in _gcd_import
  File "<frozen importlib._bootstrap>", line 1007, in _find_and_load
  File "<frozen importlib._bootstrap>", line 986, in _find_and_load_unlocked
  File "<frozen importlib._bootstrap>", line 680, in _load_unlocked
  File "<frozen importlib._bootstrap_external>", line 850, in exec_module
  File "<frozen importlib._bootstrap>", line 228, in _call_with_frames_removed
  File "/srv/casaaustin/api-casa-austin/src/config/urls.py", line 23, in <module>
    path("api/v1/", include("apps.property.urls")),
  File "/home/almalinux/.local/lib/python3.9/site-packages/django/urls/conf.py", line 38, in include
    urlconf_module = import_module(urlconf_module)
  File "/usr/lib64/python3.9/importlib/__init__.py", line 127, in import_module
    return _bootstrap._gcd_import(name[level:], package, level)
  File "<frozen importlib._bootstrap>", line 1030, in _gcd_import
  File "<frozen importlib._bootstrap>", line 1007, in _find_and_load
  File "<frozen importlib._bootstrap>", line 986, in _find_and_load_unlocked
  File "<frozen importlib._bootstrap>", line 680, in _load_unlocked
  File "<frozen importlib._bootstrap_external>", line 850, in exec_module
  File "<frozen importlib._bootstrap>", line 228, in _call_with_frames_removed
  File "/srv/casaaustin/api-casa-austin/src/apps/property/urls.py", line 1, in <module>
    from .views import (
  File "/srv/casaaustin/api-casa-austin/src/apps/property/views.py", line 3, in <module>
    from django import models
ImportError: cannot import name 'models' from 'django' (/home/almalinux/.local/lib/python3.9/site-packages/django/__init__.py)

During handling of the above exception, another exception occurred:

Traceback (most recent call last):
  File "/home/almalinux/.local/lib/python3.9/site-packages/django/core/handlers/exception.py", line 55, in inner
    response = get_response(request)
  File "/home/almalinux/.local/lib/python3.9/site-packages/corsheaders/middleware.py", line 56, in __call__
    result = self.get_response(request)
  File "/home/almalinux/.local/lib/python3.9/site-packages/django/core/handlers/exception.py", line 57, in inner
    response = response_for_exception(request, exc)
  File "/home/almalinux/.local/lib/python3.9/site-packages/django/core/handlers/exception.py", line 140, in response_for_exception
    response = handle_uncaught_exception(
  File "/home/almalinux/.local/lib/python3.9/site-packages/django/core/handlers/exception.py", line 181, in handle_uncaught_exception
    return debug.technical_500_response(request, *exc_info)
  File "/home/almalinux/.local/lib/python3.9/site-packages/django/views/debug.py", line 67, in technical_500_response
    html = reporter.get_traceback_html()
  File "/home/almalinux/.local/lib/python3.9/site-packages/django/views/debug.py", line 410, in get_traceback_html
    c = Context(self.get_traceback_data(), use_l10n=False)
  File "/home/almalinux/.local/lib/python3.9/site-packages/django/views/debug.py", line 393, in get_traceback_data
    c["raising_view_name"] = get_caller(self.request)
  File "/home/almalinux/.local/lib/python3.9/site-packages/django/views/debug.py", line 100, in get_caller
    resolver_match = resolve(request.path)
  File "/home/almalinux/.local/lib/python3.9/site-packages/django/urls/base.py", line 24, in resolve
    return get_resolver(urlconf).resolve(path)
  File "/home/almalinux/.local/lib/python3.9/site-packages/django/urls/resolvers.py", line 663, in resolve
    for pattern in self.url_patterns:
  File "/home/almalinux/.local/lib/python3.9/site-packages/django/utils/functional.py", line 57, in __get__
    res = instance.__dict__[self.name] = self.func(instance)
  File "/home/almalinux/.local/lib/python3.9/site-packages/django/urls/resolvers.py", line 715, in url_patterns
    patterns = getattr(self.urlconf_module, "urlpatterns", self.urlconf_module)
  File "/home/almalinux/.local/lib/python3.9/site-packages/django/utils/functional.py", line 57, in __get__
    res = instance.__dict__[self.name] = self.func(instance)
  File "/home/almalinux/.local/lib/python3.9/site-packages/django/urls/resolvers.py", line 708, in urlconf_module
    return import_module(self.urlconf_name)
  File "/usr/lib64/python3.9/importlib/__init__.py", line 127, in import_module
    return _bootstrap._gcd_import(name[level:], package, level)
  File "<frozen importlib._bootstrap>", line 1030, in _gcd_import
  File "<frozen importlib._bootstrap>", line 1007, in _find_and_load
  File "<frozen importlib._bootstrap>", line 986, in _find_and_load_unlocked
  File "<frozen importlib._bootstrap>", line 680, in _load_unlocked
  File "<frozen importlib._bootstrap_external>", line 850, in exec_module
  File "<frozen importlib._bootstrap>", line 228, in _call_with_frames_removed
  File "/srv/casaaustin/api-casa-austin/src/config/urls.py", line 23, in <module>
    path("api/v1/", include("apps.property.urls")),
  File "/home/almalinux/.local/lib/python3.9/site-packages/django/urls/conf.py", line 38, in include
    urlconf_module = import_module(urlconf_module)
  File "/usr/lib64/python3.9/importlib/__init__.py", line 127, in import_module
    return _bootstrap._gcd_import(name[level:], package, level)
  File "<frozen importlib._bootstrap>", line 1030, in _gcd_import
  File "<frozen importlib._bootstrap>", line 1007, in _find_and_load
  File "<frozen importlib._bootstrap>", line 986, in _find_and_load_unlocked
  File "<frozen importlib._bootstrap>", line 680, in _load_unlocked
  File "<frozen importlib._bootstrap_external>", line 850, in exec_module
  File "<frozen importlib._bootstrap>", line 228, in _call_with_frames_removed
  File "/srv/casaaustin/api-casa-austin/src/apps/property/urls.py", line 1, in <module>
    from .views import (
  File "/srv/casaaustin/api-casa-austin/src/apps/property/views.py", line 3, in <module>
    from django import models
ImportError: cannot import name 'models' from 'django' (/home/almalinux/.local/lib/python3.9/site-packages/django/__init__.py)

During handling of the above exception, another exception occurred:

Traceback (most recent call last):
  File "/home/almalinux/.local/lib/python3.9/site-packages/gunicorn/workers/sync.py", line 135, in handle
    self.handle_request(listener, req, client, addr)
  File "/home/almalinux/.local/lib/python3.9/site-packages/gunicorn/workers/sync.py", line 178, in handle_request
    respiter = self.wsgi(environ, resp.start_response)
  File "/home/almalinux/.local/lib/python3.9/site-packages/django/core/handlers/wsgi.py", line 124, in __call__
    response = self.get_response(request)
  File "/home/almalinux/.local/lib/python3.9/site-packages/django/core/handlers/base.py", line 140, in get_response
    response = self._middleware_chain(request)
  File "/home/almalinux/.local/lib/python3.9/site-packages/django/core/handlers/exception.py", line 57, in inner
    response = response_for_exception(request, exc)
  File "/home/almalinux/.local/lib/python3.9/site-packages/django/core/handlers/exception.py", line 140, in response_for_exception
    response = handle_uncaught_exception(
  File "/home/almalinux/.local/lib/python3.9/site-packages/django/core/handlers/exception.py", line 181, in handle_uncaught_exception
    return debug.technical_500_response(request, *exc_info)
  File "/home/almalinux/.local/lib/python3.9/site-packages/django/views/debug.py", line 67, in technical_500_response
    html = reporter.get_traceback_html()
  File "/home/almalinux/.local/lib/python3.9/site-packages/django/views/debug.py", line 410, in get_traceback_html
    c = Context(self.get_traceback_data(), use_l10n=False)
  File "/home/almalinux/.local/lib/python3.9/site-packages/django/views/debug.py", line 393, in get_traceback_data
    c["raising_view_name"] = get_caller(self.request)
  File "/home/almalinux/.local/lib/python3.9/site-packages/django/views/debug.py", line 100, in get_caller
    resolver_match = resolve(request.path)
  File "/home/almalinux/.local/lib/python3.9/site-packages/django/urls/base.py", line 24, in resolve
    return get_resolver(urlconf).resolve(path)
  File "/home/almalinux/.local/lib/python3.9/site-packages/django/urls/resolvers.py", line 663, in resolve
    for pattern in self.url_patterns:
  File "/home/almalinux/.local/lib/python3.9/site-packages/django/utils/functional.py", line 57, in __get__
    res = instance.__dict__[self.name] = self.func(instance)
  File "/home/almalinux/.local/lib/python3.9/site-packages/django/urls/resolvers.py", line 715, in url_patterns
    patterns = getattr(self.urlconf_module, "urlpatterns", self.urlconf_module)
  File "/home/almalinux/.local/lib/python3.9/site-packages/django/utils/functional.py", line 57, in __get__
    res = instance.__dict__[self.name] = self.func(instance)
  File "/home/almalinux/.local/lib/python3.9/site-packages/django/urls/resolvers.py", line 708, in urlconf_module
    return import_module(self.urlconf_name)
  File "/usr/lib64/python3.9/importlib/__init__.py", line 127, in import_module
    return _bootstrap._gcd_import(name[level:], package, level)
  File "<frozen importlib._bootstrap>", line 1030, in _gcd_import
  File "<frozen importlib._bootstrap>", line 1007, in _find_and_load
  File "<frozen importlib._bootstrap>", line 986, in _find_and_load_unlocked
  File "<frozen importlib._bootstrap>", line 680, in _load_unlocked
  File "<frozen importlib._bootstrap_external>", line 850, in exec_module
  File "<frozen importlib._bootstrap>", line 228, in _call_with_frames_removed
  File "/srv/casaaustin/api-casa-austin/src/config/urls.py", line 23, in <module>
    path("api/v1/", include("apps.property.urls")),
  File "/home/almalinux/.local/lib/python3.9/site-packages/django/urls/conf.py", line 38, in include
    urlconf_module = import_module(urlconf_module)
  File "/usr/lib64/python3.9/importlib/__init__.py", line 127, in import_module
    return _bootstrap._gcd_import(name[level:], package, level)
  File "<frozen importlib._bootstrap>", line 1030, in _gcd_import
  File "<frozen importlib._bootstrap>", line 1007, in _find_and_load
  File "<frozen importlib._bootstrap>", line 986, in _find_and_load_unlocked
  File "<frozen importlib._bootstrap>", line 680, in _load_unlocked
  File "<frozen importlib._bootstrap_external>", line 850, in exec_module
  File "<frozen importlib._bootstrap>", line 228, in _call_with_frames_removed
  File "/srv/casaaustin/api-casa-austin/src/apps/property/urls.py", line 1, in <module>
    from .views import (
  File "/srv/casaaustin/api-casa-austin/src/apps/property/views.py", line 3, in <module>
    from django import models
ImportError: cannot import name 'models' from 'django' (/home/almalinux/.local/lib/python3.9/site-packages/django/__init__.py