FieldError at /api/v1/music/sessions/142376b2-c597-4599-b1f9-274e5945ce58/request-access/
Cannot resolve keyword 'participant' into field. Choices are: accepted_at, client, client_id, created, deleted, id, rejected_at, requested_at, reservation, reservation_id, status, updated
Request Method:	POST
Request URL:	http://api.casaaustin.pe/api/v1/music/sessions/142376b2-c597-4599-b1f9-274e5945ce58/request-access/
Django Version:	4.2.11
Exception Type:	FieldError
Exception Value:	
Cannot resolve keyword 'participant' into field. Choices are: accepted_at, client, client_id, created, deleted, id, rejected_at, requested_at, reservation, reservation_id, status, updated
Exception Location:	/srv/casaaustin/api-casa-austin/venv-py311/lib64/python3.11/site-packages/django/db/models/sql/query.py, line 1725, in names_to_path
Raised during:	apps.reservation.music_views.RequestAccessView
Python Executable:	/srv/casaaustin/api-casa-austin/venv-py311/bin/python3.11
Python Version:	3.11.11
Python Path:	
['/srv/casaaustin/api-casa-austin/src',
 '/srv/casaaustin/api-casa-austin/venv-py311/bin',
 '/usr/lib64/python311.zip',
 '/usr/lib64/python3.11',
 '/usr/lib64/python3.11/lib-dynload',
 '/srv/casaaustin/api-casa-austin/venv-py311/lib64/python3.11/site-packages',
 '/srv/casaaustin/api-casa-austin/venv-py311/lib/python3.11/site-packages']
Server time:	Thu, 30 Oct 2025 09:07:11 -0500
Traceback Switch to copy-and-paste view
/srv/casaaustin/api-casa-austin/venv-py311/lib64/python3.11/site-packages/django/core/handlers/exception.py, line 42, in inner
    can rely on getting a response instead of an exception.
    """
    if iscoroutinefunction(get_response):
        @wraps(get_response)
        async def inner(request):
            try:
                response = await get_response(request)
                               ^^^^^^^^^^^^^^^^^^^^^^^^^^^ …
            except Exception as exc:
                response = await sync_to_async(
                    response_for_exception, thread_sensitive=False
                )(request, exc)
            return response
Local vars
/srv/casaaustin/api-casa-austin/venv-py311/lib64/python3.11/site-packages/django/core/handlers/base.py, line 253, in _get_response_async
            wrapped_callback = self.make_view_atomic(callback)
            # If it is a synchronous view, run it in a subthread
            if not iscoroutinefunction(wrapped_callback):
                wrapped_callback = sync_to_async(
                    wrapped_callback, thread_sensitive=True
                )
            try:
                response = await wrapped_callback(
                                 …
                    request, *callback_args, **callback_kwargs
                )
            except Exception as e:
                response = await sync_to_async(
                    self.process_exception_by_middleware,
                    thread_sensitive=True,
Local vars
/usr/lib64/python3.11/concurrent/futures/thread.py, line 58, in run
        self.kwargs = kwargs