Internal Server Error: /api/v1/events/my-registrations/
Traceback (most recent call last):
  File "/home/almalinux/.local/lib/python3.9/site-packages/django/db/models/fields/__init__.py", line 2055, in get_prep_value
    return int(value)
ValueError: invalid literal for int() with base 10: '405a0119-caba-467c-8f4c-835f45402367'

The above exception was the direct cause of the following exception:

Traceback (most recent call last):
  File "/home/almalinux/.local/lib/python3.9/site-packages/django/core/handlers/exception.py", line 55, in inner
    response = get_response(request)
  File "/home/almalinux/.local/lib/python3.9/site-packages/django/core/handlers/base.py", line 197, in _get_response
    response = wrapped_callback(request, *callback_args, **callback_kwargs)
  File "/home/almalinux/.local/lib/python3.9/site-packages/django/views/decorators/csrf.py", line 56, in wrapper_view
    return view_func(*args, **kwargs)
  File "/home/almalinux/.local/lib/python3.9/site-packages/django/views/generic/base.py", line 104, in view
    return self.dispatch(request, *args, **kwargs)
  File "/home/almalinux/.local/lib/python3.9/site-packages/rest_framework/views.py", line 509, in dispatch
    response = self.handle_exception(exc)
  File "/home/almalinux/.local/lib/python3.9/site-packages/rest_framework/views.py", line 469, in handle_exception
    self.raise_uncaught_exception(exc)
  File "/home/almalinux/.local/lib/python3.9/site-packages/rest_framework/views.py", line 480, in raise_uncaught_exception
    raise exc
  File "/home/almalinux/.local/lib/python3.9/site-packages/rest_framework/views.py", line 497, in dispatch
    self.initial(request, *args, **kwargs)
  File "/home/almalinux/.local/lib/python3.9/site-packages/rest_framework/views.py", line 414, in initial
    self.perform_authentication(request)
  File "/home/almalinux/.local/lib/python3.9/site-packages/rest_framework/views.py", line 324, in perform_authentication
    request.user
  File "/home/almalinux/.local/lib/python3.9/site-packages/rest_framework/request.py", line 227, in user
    self._authenticate()
  File "/home/almalinux/.local/lib/python3.9/site-packages/rest_framework/request.py", line 380, in _authenticate
    user_auth_tuple = authenticator.authenticate(self)
  File "/home/almalinux/.local/lib/python3.9/site-packages/rest_framework_simplejwt/authentication.py", line 51, in authenticate
    return self.get_user(validated_token), validated_token
  File "/home/almalinux/.local/lib/python3.9/site-packages/rest_framework_simplejwt/authentication.py", line 130, in get_user
    user = self.user_model.objects.get(**{api_settings.USER_ID_FIELD: user_id})
  File "/home/almalinux/.local/lib/python3.9/site-packages/django/db/models/manager.py", line 87, in manager_method
    return getattr(self.get_queryset(), name)(*args, **kwargs)
  File "/home/almalinux/.local/lib/python3.9/site-packages/django/db/models/query.py", line 623, in get
    clone = self._chain() if self.query.combinator else self.filter(*args, **kwargs)
  File "/home/almalinux/.local/lib/python3.9/site-packages/django/db/models/query.py", line 1436, in filter
    return self._filter_or_exclude(False, args, kwargs)
  File "/home/almalinux/.local/lib/python3.9/site-packages/django/db/models/query.py", line 1454, in _filter_or_exclude
    clone._filter_or_exclude_inplace(negate, args, kwargs)
  File "/home/almalinux/.local/lib/python3.9/site-packages/django/db/models/query.py", line 1461, in _filter_or_exclude_inplace
    self._query.add_q(Q(*args, **kwargs))
  File "/home/almalinux/.local/lib/python3.9/site-packages/django/db/models/sql/query.py", line 1498, in add_q
    clause, _ = self._add_q(q_object, self.used_aliases)
  File "/home/almalinux/.local/lib/python3.9/site-packages/django/db/models/sql/query.py", line 1529, in _add_q
    child_clause, needed_inner = self.build_filter(
  File "/home/almalinux/.local/lib/python3.9/site-packages/django/db/models/sql/query.py", line 1444, in build_filter
    condition = self.build_lookup(lookups, col, value)
  File "/home/almalinux/.local/lib/python3.9/site-packages/django/db/models/sql/query.py", line 1271, in build_lookup
    lookup = lookup_class(lhs, rhs)
  File "/home/almalinux/.local/lib/python3.9/site-packages/django/db/models/lookups.py", line 27, in __init__
    self.rhs = self.get_prep_lookup()
  File "/home/almalinux/.local/lib/python3.9/site-packages/django/db/models/lookups.py", line 341, in get_prep_lookup
    return super().get_prep_lookup()
  File "/home/almalinux/.local/lib/python3.9/site-packages/django/db/models/lookups.py", line 85, in get_prep_lookup
    return self.lhs.output_field.get_prep_value(self.rhs)
  File "/home/almalinux/.local/lib/python3.9/site-packages/django/db/models/fields/__init__.py", line 2057, in get_prep_value
    raise e.__class__(
ValueError: Field 'id' expected a number but got '405a0119-caba-467c-8f4c-835f45402367'.
ERROR 2025-09-22 04:22:47,012 log 1537870 139854119810880 Internal Server Error: /api/v1/events/my-registrations/
Traceback (most recent call last):
  File "/home/almalinux/.local/lib/python3.9/site-packages/django/db/models/fields/__init__.py", line 2055, in get_prep_value
    return int(value)
ValueError: invalid literal for int() with base 10: '405a0119-caba-467c-8f4c-835f45402367'

The above exception was the direct cause of the following exception:

Traceback (most recent call last):
  File "/home/almalinux/.local/lib/python3.9/site-packages/django/core/handlers/exception.py", line 55, in inner
    response = get_response(request)
  File "/home/almalinux/.local/lib/python3.9/site-packages/django/core/handlers/base.py", line 197, in _get_response
    response = wrapped_callback(request, *callback_args, **callback_kwargs)
  File "/home/almalinux/.local/lib/python3.9/site-packages/django/views/decorators/csrf.py", line 56, in wrapper_view
    return view_func(*args, **kwargs)
  File "/home/almalinux/.local/lib/python3.9/site-packages/django/views/generic/base.py", line 104, in view
    return self.dispatch(request, *args, **kwargs)
  File "/home/almalinux/.local/lib/python3.9/site-packages/rest_framework/views.py", line 509, in dispatch
    response = self.handle_exception(exc)
  File "/home/almalinux/.local/lib/python3.9/site-packages/rest_framework/views.py", line 469, in handle_exception
    self.raise_uncaught_exception(exc)
  File "/home/almalinux/.local/lib/python3.9/site-packages/rest_framework/views.py", line 480, in raise_uncaught_exception
    raise exc
  File "/home/almalinux/.local/lib/python3.9/site-packages/rest_framework/views.py", line 497, in dispatch
    self.initial(request, *args, **kwargs)
  File "/home/almalinux/.local/lib/python3.9/site-packages/rest_framework/views.py", line 414, in initial
    self.perform_authentication(request)
  File "/home/almalinux/.local/lib/python3.9/site-packages/rest_framework/views.py", line 324, in perform_authentication
    request.user
  File "/home/almalinux/.local/lib/python3.9/site-packages/rest_framework/request.py", line 227, in user
    self._authenticate()
  File "/home/almalinux/.local/lib/python3.9/site-packages/rest_framework/request.py", line 380, in _authenticate
    user_auth_tuple = authenticator.authenticate(self)
  File "/home/almalinux/.local/lib/python3.9/site-packages/rest_framework_simplejwt/authentication.py", line 51, in authenticate
    return self.get_user(validated_token), validated_token
  File "/home/almalinux/.local/lib/python3.9/site-packages/rest_framework_simplejwt/authentication.py", line 130, in get_user
    user = self.user_model.objects.get(**{api_settings.USER_ID_FIELD: user_id})
  File "/home/almalinux/.local/lib/python3.9/site-packages/django/db/models/manager.py", line 87, in manager_method
    return getattr(self.get_queryset(), name)(*args, **kwargs)
  File "/home/almalinux/.local/lib/python3.9/site-packages/django/db/models/query.py", line 623, in get
    clone = self._chain() if self.query.combinator else self.filter(*args, **kwargs)
  File "/home/almalinux/.local/lib/python3.9/site-packages/django/db/models/query.py", line 1436, in filter
    return self._filter_or_exclude(False, args, kwargs)
  File "/home/almalinux/.local/lib/python3.9/site-packages/django/db/models/query.py", line 1454, in _filter_or_exclude
    clone._filter_or_exclude_inplace(negate, args, kwargs)
  File "/home/almalinux/.local/lib/python3.9/site-packages/django/db/models/query.py", line 1461, in _filter_or_exclude_inplace
    self._query.add_q(Q(*args, **kwargs))
  File "/home/almalinux/.local/lib/python3.9/site-packages/django/db/models/sql/query.py", line 1498, in add_q
    clause, _ = self._add_q(q_object, self.used_aliases)
  File "/home/almalinux/.local/lib/python3.9/site-packages/django/db/models/sql/query.py", line 1529, in _add_q
    child_clause, needed_inner = self.build_filter(
  File "/home/almalinux/.local/lib/python3.9/site-packages/django/db/models/sql/query.py", line 1444, in build_filter
    condition = self.build_lookup(lookups, col, value)
  File "/home/almalinux/.local/lib/python3.9/site-packages/django/db/models/sql/query.py", line 1271, in build_lookup
    lookup = lookup_class(lhs, rhs)
  File "/home/almalinux/.local/lib/python3.9/site-packages/django/db/models/lookups.py", line 27, in __init__
    self.rhs = self.get_prep_lookup()
  File "/home/almalinux/.local/lib/python3.9/site-packages/django/db/models/lookups.py", line 341, in get_prep_lookup
    return super().get_prep_lookup()
  File "/home/almalinux/.local/lib/python3.9/site-packages/django/db/models/lookups.py", line 85, in get_prep_lookup
    return self.lhs.output_field.get_prep_value(self.rhs)
  File "/home/almalinux/.local/lib/python3.9/site-packages/django/db/models/fields/__init__.py", line 2057, in get_prep_value
    raise e.__class__(
ValueError: Field 'id' expected a number but got '405a0119-caba-467c-8f4c-835f45402367'.